Workbook

Sheet Daily
A1: Cigarette reconciliation | F1: =IF(COUNT(Data!$U:$U)=0,"No rows yet — no submitted cigarettes count, or the Counts query is not attached",IF(COUNTIFS(Data!$R$2:$R$1048576,"<>",Data!$R$2:$R$1048576,"<>CIGARETTES")>0,"WRONG QUERY: this sheet has rows that are not CIGARETTES — reattach Counts","Safari · "&COUNT(Calc!$B$3:$B$62)&" days loaded, latest "&TEXT(MAX(Data!$B:$B),"dd mmm yyyy"))) | L1: =IFERROR(MATCH($B$3,Calc!$B$3:$B$62,0),"")
A2: TRADING DAY (CLOSING) | D2: OPENING FROM | F2: COUNTED BY | H2: PRODUCTS
A3: Show: | B3: =IFERROR(INDEX(Data!$B:$B,MATCH(1,Data!$U:$U,0)),"") | D3: =IF($L$1="","—",IF(INDEX(Calc!$D$3:$D$62,$L$1)="","—",INDEX(Calc!$D$3:$D$62,$L$1))) | F3: =IF($L$1="","—",IF(INDEX(Calc!$C$3:$C$62,$L$1)="","—",INDEX(Calc!$C$3:$C$62,$L$1))) | H3: =IF($L$1="","—",IF(INDEX(Calc!$E$3:$E$62,$L$1)="","—",INDEX(Calc!$E$3:$E$62,$L$1)))
A5: PRODUCTS WITH VARIANCE | D5: TOTAL VARIANCE (PACKS) | F5: TOTAL VARIANCE (RM) | H5: POS SALES
A6: =IF($L$1="","—",IF(INDEX(Calc!$H$3:$H$62,$L$1)="","—",INDEX(Calc!$H$3:$H$62,$L$1))) | D6: =IF($L$1="","—",IF(INDEX(Calc!$I$3:$I$62,$L$1)="","—",INDEX(Calc!$I$3:$I$62,$L$1))) | F6: =IF($L$1="","—",IF(INDEX(Calc!$K$3:$K$62,$L$1)="","—",INDEX(Calc!$K$3:$K$62,$L$1))) | H6: =IF($L$1="","—",IF(INDEX(Calc!$M$3:$M$62,$L$1)="","—",INDEX(Calc!$M$3:$M$62,$L$1)))
A7: =IF(COUNT(Data!$U:$U)=0,"Nothing to show yet. Either no cigarettes count has been submitted, or the Counts query is not attached — see the Setup sheet.",IF($L$1="","—",IF(INDEX(Calc!$O$3:$O$62,$L$1)="","—",INDEX(Calc!$O$3:$O$62,$L$1))))
A9: Product | B9: Opening | C9: Added | D9: Closing | E9: Sold (counted) | F9: Sold (POS) | G9: Variance | H9: Variance RM | I9: Item ID | J9: PLU
A10: =IF(AND(ISNUMBER($L10),$L10<>""),INDEX(Data!$G:$G,$L10),"") | B10: =IF(AND(ISNUMBER($L10),$L10<>""),IF(INDEX(Data!$I:$I,$L10)="","—",INDEX(Data!$I:$I,$L10)),"") | C10: =IF(AND(ISNUMBER($L10),$L10<>""),INDEX(Data!$J:$J,$L10),"") | D10: =IF(AND(ISNUMBER($L10),$L10<>""),INDEX(Data!$K:$K,$L10),"") | E10: =IF(AND(ISNUMBER($L10),$L10<>""),IF(INDEX(Data!$L:$L,$L10)="","—",INDEX(Data!$L:$L,$L10)),"") | F10: =IF(AND(ISNUMBER($L10),$L10<>""),IF(INDEX(Data!$M:$M,$L10)="","—",INDEX(Data!$M:$M,$L10)),"") | G10: =IF(AND(ISNUMBER($L10),$L10<>""),IF(INDEX(Data!$N:$N,$L10)="","—",INDEX(Data!$N:$N,$L10)),"") | H10: =IF(AND(ISNUMBER($L10),$L10<>""),IF(INDEX(Data!$Q:$Q,$L10)="","—",INDEX(Data!$Q:$Q,$L10)),"") | I10: =IF(AND(ISNUMBER($L10),$L10<>""),INDEX(Data!$E:$E,$L10),"") | J10: =IF(AND(ISNUMBER($L10),$L10<>""),INDEX(Data!$F:$F,$L10),"") | L10: =IFERROR(MATCH((YEAR($B$3)*10000+MONTH($B$3)*100+DAY($B$3))*1000+1,Data!$W:$W,0),"")
A11: =IF(AND(ISNUMBER($L11),$L11<>""),INDEX(Data!$G:$G,$L11),"") | B11: =IF(AND(ISNUMBER($L11),$L11<>""),IF(INDEX(Data!$I:$I,$L11)="","—",INDEX(Data!$I:$I,$L11)),"") | C11: =IF(AND(ISNUMBER($L11),$L11<>""),INDEX(Data!$J:$J,$L11),"") | D11: =IF(AND(ISNUMBER($L11),$L11<>""),INDEX(Data!$K:$K,$L11),"") | E11: =IF(AND(ISNUMBER($L11),$L11<>""),IF(INDEX(Data!$L:$L,$L11)="","—",INDEX(Data!$L:$L,$L11)),"") | F11: =IF(AND(ISNUMBER($L11),$L11<>""),IF(INDEX(Data!$M:$M,$L11)="","—",INDEX(Data!$M:$M,$L11)),"") | G11: =IF(AND(ISNUMBER($L11),$L11<>""),IF(INDEX(Data!$N:$N,$L11)="","—",INDEX(Data!$N:$N,$L11)),"") | H11: =IF(AND(ISNUMBER($L11),$L11<>""),IF(INDEX(Data!$Q:$Q,$L11)="","—",INDEX(Data!$Q:$Q,$L11)),"") | I11: =IF(AND(ISNUMBER($L11),$L11<>""),INDEX(Data!$E:$E,$L11),"") | J11: =IF(AND(ISNUMBER($L11),$L11<>""),INDEX(Data!$F:$F,$L11),"") | L11: =IFERROR(MATCH((YEAR($B$3)*10000+MONTH($B$3)*100+DAY($B$3))*1000+2,Data!$W:$W,0),"")
A12: =IF(AND(ISNUMBER($L12),$L12<>""),INDEX(Data!$G:$G,$L12),"") | B12: =IF(AND(ISNUMBER($L12),$L12<>""),IF(INDEX(Data!$I:$I,$L12)="","—",INDEX(Data!$I:$I,$L12)),"") | C12: =IF(AND(ISNUMBER($L12),$L12<>""),INDEX(Data!$J:$J,$L12),"") | D12: =IF(AND(ISNUMBER($L12),$L12<>""),INDEX(Data!$K:$K,$L12),"") | E12: =IF(AND(ISNUMBER($L12),$L12<>""),IF(INDEX(Data!$L:$L,$L12)="","—",INDEX(Data!$L:$L,$L12)),"") | F12: =IF(AND(ISNUMBER($L12),$L12<>""),IF(INDEX(Data!$M:$M,$L12)="","—",INDEX(Data!$M:$M,$L12)),"") | G12: =IF(AND(ISNUMBER($L12),$L12<>""),IF(INDEX(Data!$N:$N,$L12)="","—",INDEX(Data!$N:$N,$L12)),"") | H12: =IF(AND(ISNUMBER($L12),$L12<>""),IF(INDEX(Data!$Q:$Q,$L12)="","—",INDEX(Data!$Q:$Q,$L12)),"") | I12: =IF(AND(ISNUMBER($L12),$L12<>""),INDEX(Data!$E:$E,$L12),"") | J12: =IF(AND(ISNUMBER($L12),$L12<>""),INDEX(Data!$F:$F,$L12),"") | L12: =IFERROR(MATCH((YEAR($B$3)*10000+MONTH($B$3)*100+DAY($B$3))*1000+3,Data!$W:$W,0),"")
A13: =IF(AND(ISNUMBER($L13),$L13<>""),INDEX(Data!$G:$G,$L13),"") | B13: =IF(AND(ISNUMBER($L13),$L13<>""),IF(INDEX(Data!$I:$I,$L13)="","—",INDEX(Data!$I:$I,$L13)),"") | C13: =IF(AND(ISNUMBER($L13),$L13<>""),INDEX(Data!$J:$J,$L13),"") | D13: =IF(AND(ISNUMBER($L13),$L13<>""),INDEX(Data!$K:$K,$L13),"") | E13: =IF(AND(ISNUMBER($L13),$L13<>""),IF(INDEX(Data!$L:$L,$L13)="","—",INDEX(Data!$L:$L,$L13)),"") | F13: =IF(AND(ISNUMBER($L13),$L13<>""),IF(INDEX(Data!$M:$M,$L13)="","—",INDEX(Data!$M:$M,$L13)),"") | G13: =IF(AND(ISNUMBER($L13),$L13<>""),IF(INDEX(Data!$N:$N,$L13)="","—",INDEX(Data!$N:$N,$L13)),"") | H13: =IF(AND(ISNUMBER($L13),$L13<>""),IF(INDEX(Data!$Q:$Q,$L13)="","—",INDEX(Data!$Q:$Q,$L13)),"") | I13: =IF(AND(ISNUMBER($L13),$L13<>""),INDEX(Data!$E:$E,$L13),"") | J13: =IF(AND(ISNUMBER($L13),$L13<>""),INDEX(Data!$F:$F,$L13),"") | L13: =IFERROR(MATCH((YEAR($B$3)*10000+MONTH($B$3)*100+DAY($B$3))*1000+4,Data!$W:$W,0),"")
A14: =IF(AND(ISNUMBER($L14),$L14<>""),INDEX(Data!$G:$G,$L14),"") | B14: =IF(AND(ISNUMBER($L14),$L14<>""),IF(INDEX(Data!$I:$I,$L14)="","—",INDEX(Data!$I:$I,$L14)),"") | C14: =IF(AND(ISNUMBER($L14),$L14<>""),INDEX(Data!$J:$J,$L14),"") | D14: =IF(AND(ISNUMBER($L14),$L14<>""),INDEX(Data!$K:$K,$L14),"") | E14: =IF(AND(ISNUMBER($L14),$L14<>""),IF(INDEX(Data!$L:$L,$L14)="","—",INDEX(Data!$L:$L,$L14)),"") | F14: =IF(AND(ISNUMBER($L14),$L14<>""),IF(INDEX(Data!$M:$M,$L14)="","—",INDEX(Data!$M:$M,$L14)),"") | G14: =IF(AND(ISNUMBER($L14),$L14<>""),IF(INDEX(Data!$N:$N,$L14)="","—",INDEX(Data!$N:$N,$L14)),"") | H14: =IF(AND(ISNUMBER($L14),$L14<>""),IF(INDEX(Data!$Q:$Q,$L14)="","—",INDEX(Data!$Q:$Q,$L14)),"") | I14: =IF(AND(ISNUMBER($L14),$L14<>""),INDEX(Data!$E:$E,$L14),"") | J14: =IF(AND(ISNUMBER($L14),$L14<>""),INDEX(Data!$F:$F,$L14),"") | L14: =IFERROR(MATCH((YEAR($B$3)*10000+MONTH($B$3)*100+DAY($B$3))*1000+5,Data!$W:$W,0),"")
A15: =IF(AND(ISNUMBER($L15),$L15<>""),INDEX(Data!$G:$G,$L15),"") | B15: =IF(AND(ISNUMBER($L15),$L15<>""),IF(INDEX(Data!$I:$I,$L15)="","—",INDEX(Data!$I:$I,$L15)),"") | C15: =IF(AND(ISNUMBER($L15),$L15<>""),INDEX(Data!$J:$J,$L15),"") | D15: =IF(AND(ISNUMBER($L15),$L15<>""),INDEX(Data!$K:$K,$L15),"") | E15: =IF(AND(ISNUMBER($L15),$L15<>""),IF(INDEX(Data!$L:$L,$L15)="","—",INDEX(Data!$L:$L,$L15)),"") | F15: =IF(AND(ISNUMBER($L15),$L15<>""),IF(INDEX(Data!$M:$M,$L15)="","—",INDEX(Data!$M:$M,$L15)),"") | G15: =IF(AND(ISNUMBER($L15),$L15<>""),IF(INDEX(Data!$N:$N,$L15)="","—",INDEX(Data!$N:$N,$L15)),"") | H15: =IF(AND(ISNUMBER($L15),$L15<>""),IF(INDEX(Data!$Q:$Q,$L15)="","—",INDEX(Data!$Q:$Q,$L15)),"") | I15: =IF(AND(ISNUMBER($L15),$L15<>""),INDEX(Data!$E:$E,$L15),"") | J15: =IF(AND(ISNUMBER($L15),$L15<>""),INDEX(Data!$F:$F,$L15),"") | L15: =IFERROR(MATCH((YEAR($B$3)*10000+MONTH($B$3)*100+DAY($B$3))*1000+6,Data!$W:$W,0),"")
A16: =IF(AND(ISNUMBER($L16),$L16<>""),INDEX(Data!$G:$G,$L16),"") | B16: =IF(AND(ISNUMBER($L16),$L16<>""),IF(INDEX(Data!$I:$I,$L16)="","—",INDEX(Data!$I:$I,$L16)),"") | C16: =IF(AND(ISNUMBER($L16),$L16<>""),INDEX(Data!$J:$J,$L16),"") | D16: =IF(AND(ISNUMBER($L16),$L16<>""),INDEX(Data!$K:$K,$L16),"") | E16: =IF(AND(ISNUMBER($L16),$L16<>""),IF(INDEX(Data!$L:$L,$L16)="","—",INDEX(Data!$L:$L,$L16)),"") | F16: =IF(AND(ISNUMBER($L16),$L16<>""),IF(INDEX(Data!$M:$M,$L16)="","—",INDEX(Data!$M:$M,$L16)),"") | G16: =IF(AND(ISNUMBER($L16),$L16<>""),IF(INDEX(Data!$N:$N,$L16)="","—",INDEX(Data!$N:$N,$L16)),"") | H16: =IF(AND(ISNUMBER($L16),$L16<>""),IF(INDEX(Data!$Q:$Q,$L16)="","—",INDEX(Data!$Q:$Q,$L16)),"") | I16: =IF(AND(ISNUMBER($L16),$L16<>""),INDEX(Data!$E:$E,$L16),"") | J16: =IF(AND(ISNUMBER($L16),$L16<>""),INDEX(Data!$F:$F,$L16),"") | L16: =IFERROR(MATCH((YEAR($B$3)*10000+MONTH($B$3)*100+DAY($B$3))*1000+7,Data!$W:$W,0),"")
A17: =IF(AND(ISNUMBER($L17),$L17<>""),INDEX(Data!$G:$G,$L17),"") | B17: =IF(AND(ISNUMBER($L17),$L17<>""),IF(INDEX(Data!$I:$I,$L17)="","—",INDEX(Data!$I:$I,$L17)),"") | C17: =IF(AND(ISNUMBER($L17),$L17<>""),INDEX(Data!$J:$J,$L17),"") | D17: =IF(AND(ISNUMBER($L17),$L17<>""),INDEX(Data!$K:$K,$L17),"") | E17: =IF(AND(ISNUMBER($L17),$L17<>""),IF(INDEX(Data!$L:$L,$L17)="","—",INDEX(Data!$L:$L,$L17)),"") | F17: =IF(AND(ISNUMBER($L17),$L17<>""),IF(INDEX(Data!$M:$M,$L17)="","—",INDEX(Data!$M:$M,$L17)),"") | G17: =IF(AND(ISNUMBER($L17),$L17<>""),IF(INDEX(Data!$N:$N,$L17)="","—",INDEX(Data!$N:$N,$L17)),"") | H17: =IF(AND(ISNUMBER($L17),$L17<>""),IF(INDEX(Data!$Q:$Q,$L17)="","—",INDEX(Data!$Q:$Q,$L17)),"") | I17: =IF(AND(ISNUMBER($L17),$L17<>""),INDEX(Data!$E:$E,$L17),"") | J17: =IF(AND(ISNUMBER($L17),$L17<>""),INDEX(Data!$F:$F,$L17),"") | L17: =IFERROR(MATCH((YEAR($B$3)*10000+MONTH($B$3)*100+DAY($B$3))*1000+8,Data!$W:$W,0),"")
A18: =IF(AND(ISNUMBER($L18),$L18<>""),INDEX(Data!$G:$G,$L18),"") | B18: =IF(AND(ISNUMBER($L18),$L18<>""),IF(INDEX(Data!$I:$I,$L18)="","—",INDEX(Data!$I:$I,$L18)),"") | C18: =IF(AND(ISNUMBER($L18),$L18<>""),INDEX(Data!$J:$J,$L18),"") | D18: =IF(AND(ISNUMBER($L18),$L18<>""),INDEX(Data!$K:$K,$L18),"") | E18: =IF(AND(ISNUMBER($L18),$L18<>""),IF(INDEX(Data!$L:$L,$L18)="","—",INDEX(Data!$L:$L,$L18)),"") | F18: =IF(AND(ISNUMBER($L18),$L18<>""),IF(INDEX(Data!$M:$M,$L18)="","—",INDEX(Data!$M:$M,$L18)),"") | G18: =IF(AND(ISNUMBER($L18),$L18<>""),IF(INDEX(Data!$N:$N,$L18)="","—",INDEX(Data!$N:$N,$L18)),"") | H18: =IF(AND(ISNUMBER($L18),$L18<>""),IF(INDEX(Data!$Q:$Q,$L18)="","—",INDEX(Data!$Q:$Q,$L18)),"") | I18: =IF(AND(ISNUMBER($L18),$L18<>""),INDEX(Data!$E:$E,$L18),"") | J18: =IF(AND(ISNUMBER($L18),$L18<>""),INDEX(Data!$F:$F,$L18),"") | L18: =IFERROR(MATCH((YEAR($B$3)*10000+MONTH($B$3)*100+DAY($B$3))*1000+9,Data!$W:$W,0),"")
A19: =IF(AND(ISNUMBER($L19),$L19<>""),INDEX(Data!$G:$G,$L19),"") | B19: =IF(AND(ISNUMBER($L19),$L19<>""),IF(INDEX(Data!$I:$I,$L19)="","—",INDEX(Data!$I:$I,$L19)),"") | C19: =IF(AND(ISNUMBER($L19),$L19<>""),INDEX(Data!$J:$J,$L19),"") | D19: =IF(AND(ISNUMBER($L19),$L19<>""),INDEX(Data!$K:$K,$L19),"") | E19: =IF(AND(ISNUMBER($L19),$L19<>""),IF(INDEX(Data!$L:$L,$L19)="","—",INDEX(Data!$L:$L,$L19)),"") | F19: =IF(AND(ISNUMBER($L19),$L19<>""),IF(INDEX(Data!$M:$M,$L19)="","—",INDEX(Data!$M:$M,$L19)),"") | G19: =IF(AND(ISNUMBER($L19),$L19<>""),IF(INDEX(Data!$N:$N,$L19)="","—",INDEX(Data!$N:$N,$L19)),"") | H19: =IF(AND(ISNUMBER($L19),$L19<>""),IF(INDEX(Data!$Q:$Q,$L19)="","—",INDEX(Data!$Q:$Q,$L19)),"") | I19: =IF(AND(ISNUMBER($L19),$L19<>""),INDEX(Data!$E:$E,$L19),"") | J19: =IF(AND(ISNUMBER($L19),$L19<>""),INDEX(Data!$F:$F,$L19),"") | L19: =IFERROR(MATCH((YEAR($B$3)*10000+MONTH($B$3)*100+DAY($B$3))*1000+10,Data!$W:$W,0),"")
A20: =IF(AND(ISNUMBER($L20),$L20<>""),INDEX(Data!$G:$G,$L20),"") | B20: =IF(AND(ISNUMBER($L20),$L20<>""),IF(INDEX(Data!$I:$I,$L20)="","—",INDEX(Data!$I:$I,$L20)),"") | C20: =IF(AND(ISNUMBER($L20),$L20<>""),INDEX(Data!$J:$J,$L20),"") | D20: =IF(AND(ISNUMBER($L20),$L20<>""),INDEX(Data!$K:$K,$L20),"") | E20: =IF(AND(ISNUMBER($L20),$L20<>""),IF(INDEX(Data!$L:$L,$L20)="","—",INDEX(Data!$L:$L,$L20)),"") | F20: =IF(AND(ISNUMBER($L20),$L20<>""),IF(INDEX(Data!$M:$M,$L20)="","—",INDEX(Data!$M:$M,$L20)),"") | G20: =IF(AND(ISNUMBER($L20),$L20<>""),IF(INDEX(Data!$N:$N,$L20)="","—",INDEX(Data!$N:$N,$L20)),"") | H20: =IF(AND(ISNUMBER($L20),$L20<>""),IF(INDEX(Data!$Q:$Q,$L20)="","—",INDEX(Data!$Q:$Q,$L20)),"") | I20: =IF(AND(ISNUMBER($L20),$L20<>""),INDEX(Data!$E:$E,$L20),"") | J20: =IF(AND(ISNUMBER($L20),$L20<>""),INDEX(Data!$F:$F,$L20),"") | L20: =IFERROR(MATCH((YEAR($B$3)*10000+MONTH($B$3)*100+DAY($B$3))*1000+11,Data!$W:$W,0),"")
A21: =IF(AND(ISNUMBER($L21),$L21<>""),INDEX(Data!$G:$G,$L21),"") | B21: =IF(AND(ISNUMBER($L21),$L21<>""),IF(INDEX(Data!$I:$I,$L21)="","—",INDEX(Data!$I:$I,$L21)),"") | C21: =IF(AND(ISNUMBER($L21),$L21<>""),INDEX(Data!$J:$J,$L21),"") | D21: =IF(AND(ISNUMBER($L21),$L21<>""),INDEX(Data!$K:$K,$L21),"") | E21: =IF(AND(ISNUMBER($L21),$L21<>""),IF(INDEX(Data!$L:$L,$L21)="","—",INDEX(Data!$L:$L,$L21)),"") | F21: =IF(AND(ISNUMBER($L21),$L21<>""),IF(INDEX(Data!$M:$M,$L21)="","—",INDEX(Data!$M:$M,$L21)),"") | G21: =IF(AND(ISNUMBER($L21),$L21<>""),IF(INDEX(Data!$N:$N,$L21)="","—",INDEX(Data!$N:$N,$L21)),"") | H21: =IF(AND(ISNUMBER($L21),$L21<>""),IF(INDEX(Data!$Q:$Q,$L21)="","—",INDEX(Data!$Q:$Q,$L21)),"") | I21: =IF(AND(ISNUMBER($L21),$L21<>""),INDEX(Data!$E:$E,$L21),"") | J21: =IF(AND(ISNUMBER($L21),$L21<>""),INDEX(Data!$F:$F,$L21),"") | L21: =IFERROR(MATCH((YEAR($B$3)*10000+MONTH($B$3)*100+DAY($B$3))*1000+12,Data!$W:$W,0),"")
A22: =IF(AND(ISNUMBER($L22),$L22<>""),INDEX(Data!$G:$G,$L22),"") | B22: =IF(AND(ISNUMBER($L22),$L22<>""),IF(INDEX(Data!$I:$I,$L22)="","—",INDEX(Data!$I:$I,$L22)),"") | C22: =IF(AND(ISNUMBER($L22),$L22<>""),INDEX(Data!$J:$J,$L22),"") | D22: =IF(AND(ISNUMBER($L22),$L22<>""),INDEX(Data!$K:$K,$L22),"") | E22: =IF(AND(ISNUMBER($L22),$L22<>""),IF(INDEX(Data!$L:$L,$L22)="","—",INDEX(Data!$L:$L,$L22)),"") | F22: =IF(AND(ISNUMBER($L22),$L22<>""),IF(INDEX(Data!$M:$M,$L22)="","—",INDEX(Data!$M:$M,$L22)),"") | G22: =IF(AND(ISNUMBER($L22),$L22<>""),IF(INDEX(Data!$N:$N,$L22)="","—",INDEX(Data!$N:$N,$L22)),"") | H22: =IF(AND(ISNUMBER($L22),$L22<>""),IF(INDEX(Data!$Q:$Q,$L22)="","—",INDEX(Data!$Q:$Q,$L22)),"") | I22: =IF(AND(ISNUMBER($L22),$L22<>""),INDEX(Data!$E:$E,$L22),"") | J22: =IF(AND(ISNUMBER($L22),$L22<>""),INDEX(Data!$F:$F,$L22),"") | L22: =IFERROR(MATCH((YEAR($B$3)*10000+MONTH($B$3)*100+DAY($B$3))*1000+13,Data!$W:$W,0),"")
A23: =IF(AND(ISNUMBER($L23),$L23<>""),INDEX(Data!$G:$G,$L23),"") | B23: =IF(AND(ISNUMBER($L23),$L23<>""),IF(INDEX(Data!$I:$I,$L23)="","—",INDEX(Data!$I:$I,$L23)),"") | C23: =IF(AND(ISNUMBER($L23),$L23<>""),INDEX(Data!$J:$J,$L23),"") | D23: =IF(AND(ISNUMBER($L23),$L23<>""),INDEX(Data!$K:$K,$L23),"") | E23: =IF(AND(ISNUMBER($L23),$L23<>""),IF(INDEX(Data!$L:$L,$L23)="","—",INDEX(Data!$L:$L,$L23)),"") | F23: =IF(AND(ISNUMBER($L23),$L23<>""),IF(INDEX(Data!$M:$M,$L23)="","—",INDEX(Data!$M:$M,$L23)),"") | G23: =IF(AND(ISNUMBER($L23),$L23<>""),IF(INDEX(Data!$N:$N,$L23)="","—",INDEX(Data!$N:$N,$L23)),"") | H23: =IF(AND(ISNUMBER($L23),$L23<>""),IF(INDEX(Data!$Q:$Q,$L23)="","—",INDEX(Data!$Q:$Q,$L23)),"") | I23: =IF(AND(ISNUMBER($L23),$L23<>""),INDEX(Data!$E:$E,$L23),"") | J23: =IF(AND(ISNUMBER($L23),$L23<>""),INDEX(Data!$F:$F,$L23),"") | L23: =IFERROR(MATCH((YEAR($B$3)*10000+MONTH($B$3)*100+DAY($B$3))*1000+14,Data!$W:$W,0),"")
A24: =IF(AND(ISNUMBER($L24),$L24<>""),INDEX(Data!$G:$G,$L24),"") | B24: =IF(AND(ISNUMBER($L24),$L24<>""),IF(INDEX(Data!$I:$I,$L24)="","—",INDEX(Data!$I:$I,$L24)),"") | C24: =IF(AND(ISNUMBER($L24),$L24<>""),INDEX(Data!$J:$J,$L24),"") | D24: =IF(AND(ISNUMBER($L24),$L24<>""),INDEX(Data!$K:$K,$L24),"") | E24: =IF(AND(ISNUMBER($L24),$L24<>""),IF(INDEX(Data!$L:$L,$L24)="","—",INDEX(Data!$L:$L,$L24)),"") | F24: =IF(AND(ISNUMBER($L24),$L24<>""),IF(INDEX(Data!$M:$M,$L24)="","—",INDEX(Data!$M:$M,$L24)),"") | G24: =IF(AND(ISNUMBER($L24),$L24<>""),IF(INDEX(Data!$N:$N,$L24)="","—",INDEX(Data!$N:$N,$L24)),"") | H24: =IF(AND(ISNUMBER($L24),$L24<>""),IF(INDEX(Data!$Q:$Q,$L24)="","—",INDEX(Data!$Q:$Q,$L24)),"") | I24: =IF(AND(ISNUMBER($L24),$L24<>""),INDEX(Data!$E:$E,$L24),"") | J24: =IF(AND(ISNUMBER($L24),$L24<>""),INDEX(Data!$F:$F,$L24),"") | L24: =IFERROR(MATCH((YEAR($B$3)*10000+MONTH($B$3)*100+DAY($B$3))*1000+15,Data!$W:$W,0),"")
A25: =IF(AND(ISNUMBER($L25),$L25<>""),INDEX(Data!$G:$G,$L25),"") | B25: =IF(AND(ISNUMBER($L25),$L25<>""),IF(INDEX(Data!$I:$I,$L25)="","—",INDEX(Data!$I:$I,$L25)),"") | C25: =IF(AND(ISNUMBER($L25),$L25<>""),INDEX(Data!$J:$J,$L25),"") | D25: =IF(AND(ISNUMBER($L25),$L25<>""),INDEX(Data!$K:$K,$L25),"") | E25: =IF(AND(ISNUMBER($L25),$L25<>""),IF(INDEX(Data!$L:$L,$L25)="","—",INDEX(Data!$L:$L,$L25)),"") | F25: =IF(AND(ISNUMBER($L25),$L25<>""),IF(INDEX(Data!$M:$M,$L25)="","—",INDEX(Data!$M:$M,$L25)),"") | G25: =IF(AND(ISNUMBER($L25),$L25<>""),IF(INDEX(Data!$N:$N,$L25)="","—",INDEX(Data!$N:$N,$L25)),"") | H25: =IF(AND(ISNUMBER($L25),$L25<>""),IF(INDEX(Data!$Q:$Q,$L25)="","—",INDEX(Data!$Q:$Q,$L25)),"") | I25: =IF(AND(ISNUMBER($L25),$L25<>""),INDEX(Data!$E:$E,$L25),"") | J25: =IF(AND(ISNUMBER($L25),$L25<>""),INDEX(Data!$F:$F,$L25),"") | L25: =IFERROR(MATCH((YEAR($B$3)*10000+MONTH($B$3)*100+DAY($B$3))*1000+16,Data!$W:$W,0),"")
A26: =IF(AND(ISNUMBER($L26),$L26<>""),INDEX(Data!$G:$G,$L26),"") | B26: =IF(AND(ISNUMBER($L26),$L26<>""),IF(INDEX(Data!$I:$I,$L26)="","—",INDEX(Data!$I:$I,$L26)),"") | C26: =IF(AND(ISNUMBER($L26),$L26<>""),INDEX(Data!$J:$J,$L26),"") | D26: =IF(AND(ISNUMBER($L26),$L26<>""),INDEX(Data!$K:$K,$L26),"") | E26: =IF(AND(ISNUMBER($L26),$L26<>""),IF(INDEX(Data!$L:$L,$L26)="","—",INDEX(Data!$L:$L,$L26)),"") | F26: =IF(AND(ISNUMBER($L26),$L26<>""),IF(INDEX(Data!$M:$M,$L26)="","—",INDEX(Data!$M:$M,$L26)),"") | G26: =IF(AND(ISNUMBER($L26),$L26<>""),IF(INDEX(Data!$N:$N,$L26)="","—",INDEX(Data!$N:$N,$L26)),"") | H26: =IF(AND(ISNUMBER($L26),$L26<>""),IF(INDEX(Data!$Q:$Q,$L26)="","—",INDEX(Data!$Q:$Q,$L26)),"") | I26: =IF(AND(ISNUMBER($L26),$L26<>""),INDEX(Data!$E:$E,$L26),"") | J26: =IF(AND(ISNUMBER($L26),$L26<>""),INDEX(Data!$F:$F,$L26),"") | L26: =IFERROR(MATCH((YEAR($B$3)*10000+MONTH($B$3)*100+DAY($B$3))*1000+17,Data!$W:$W,0),"")
A27: =IF(AND(ISNUMBER($L27),$L27<>""),INDEX(Data!$G:$G,$L27),"") | B27: =IF(AND(ISNUMBER($L27),$L27<>""),IF(INDEX(Data!$I:$I,$L27)="","—",INDEX(Data!$I:$I,$L27)),"") | C27: =IF(AND(ISNUMBER($L27),$L27<>""),INDEX(Data!$J:$J,$L27),"") | D27: =IF(AND(ISNUMBER($L27),$L27<>""),INDEX(Data!$K:$K,$L27),"") | E27: =IF(AND(ISNUMBER($L27),$L27<>""),IF(INDEX(Data!$L:$L,$L27)="","—",INDEX(Data!$L:$L,$L27)),"") | F27: =IF(AND(ISNUMBER($L27),$L27<>""),IF(INDEX(Data!$M:$M,$L27)="","—",INDEX(Data!$M:$M,$L27)),"") | G27: =IF(AND(ISNUMBER($L27),$L27<>""),IF(INDEX(Data!$N:$N,$L27)="","—",INDEX(Data!$N:$N,$L27)),"") | H27: =IF(AND(ISNUMBER($L27),$L27<>""),IF(INDEX(Data!$Q:$Q,$L27)="","—",INDEX(Data!$Q:$Q,$L27)),"") | I27: =IF(AND(ISNUMBER($L27),$L27<>""),INDEX(Data!$E:$E,$L27),"") | J27: =IF(AND(ISNUMBER($L27),$L27<>""),INDEX(Data!$F:$F,$L27),"") | L27: =IFERROR(MATCH((YEAR($B$3)*10000+MONTH($B$3)*100+DAY($B$3))*1000+18,Data!$W:$W,0),"")
A28: =IF(AND(ISNUMBER($L28),$L28<>""),INDEX(Data!$G:$G,$L28),"") | B28: =IF(AND(ISNUMBER($L28),$L28<>""),IF(INDEX(Data!$I:$I,$L28)="","—",INDEX(Data!$I:$I,$L28)),"") | C28: =IF(AND(ISNUMBER($L28),$L28<>""),INDEX(Data!$J:$J,$L28),"") | D28: =IF(AND(ISNUMBER($L28),$L28<>""),INDEX(Data!$K:$K,$L28),"") | E28: =IF(AND(ISNUMBER($L28),$L28<>""),IF(INDEX(Data!$L:$L,$L28)="","—",INDEX(Data!$L:$L,$L28)),"") | F28: =IF(AND(ISNUMBER($L28),$L28<>""),IF(INDEX(Data!$M:$M,$L28)="","—",INDEX(Data!$M:$M,$L28)),"") | G28: =IF(AND(ISNUMBER($L28),$L28<>""),IF(INDEX(Data!$N:$N,$L28)="","—",INDEX(Data!$N:$N,$L28)),"") | H28: =IF(AND(ISNUMBER($L28),$L28<>""),IF(INDEX(Data!$Q:$Q,$L28)="","—",INDEX(Data!$Q:$Q,$L28)),"") | I28: =IF(AND(ISNUMBER($L28),$L28<>""),INDEX(Data!$E:$E,$L28),"") | J28: =IF(AND(ISNUMBER($L28),$L28<>""),INDEX(Data!$F:$F,$L28),"") | L28: =IFERROR(MATCH((YEAR($B$3)*10000+MONTH($B$3)*100+DAY($B$3))*1000+19,Data!$W:$W,0),"")
A29: =IF(AND(ISNUMBER($L29),$L29<>""),INDEX(Data!$G:$G,$L29),"") | B29: =IF(AND(ISNUMBER($L29),$L29<>""),IF(INDEX(Data!$I:$I,$L29)="","—",INDEX(Data!$I:$I,$L29)),"") | C29: =IF(AND(ISNUMBER($L29),$L29<>""),INDEX(Data!$J:$J,$L29),"") | D29: =IF(AND(ISNUMBER($L29),$L29<>""),INDEX(Data!$K:$K,$L29),"") | E29: =IF(AND(ISNUMBER($L29),$L29<>""),IF(INDEX(Data!$L:$L,$L29)="","—",INDEX(Data!$L:$L,$L29)),"") | F29: =IF(AND(ISNUMBER($L29),$L29<>""),IF(INDEX(Data!$M:$M,$L29)="","—",INDEX(Data!$M:$M,$L29)),"") | G29: =IF(AND(ISNUMBER($L29),$L29<>""),IF(INDEX(Data!$N:$N,$L29)="","—",INDEX(Data!$N:$N,$L29)),"") | H29: =IF(AND(ISNUMBER($L29),$L29<>""),IF(INDEX(Data!$Q:$Q,$L29)="","—",INDEX(Data!$Q:$Q,$L29)),"") | I29: =IF(AND(ISNUMBER($L29),$L29<>""),INDEX(Data!$E:$E,$L29),"") | J29: =IF(AND(ISNUMBER($L29),$L29<>""),INDEX(Data!$F:$F,$L29),"") | L29: =IFERROR(MATCH((YEAR($B$3)*10000+MONTH($B$3)*100+DAY($B$3))*1000+20,Data!$W:$W,0),"")
A30: =IF(AND(ISNUMBER($L30),$L30<>""),INDEX(Data!$G:$G,$L30),"") | B30: =IF(AND(ISNUMBER($L30),$L30<>""),IF(INDEX(Data!$I:$I,$L30)="","—",INDEX(Data!$I:$I,$L30)),"") | C30: =IF(AND(ISNUMBER($L30),$L30<>""),INDEX(Data!$J:$J,$L30),"") | D30: =IF(AND(ISNUMBER($L30),$L30<>""),INDEX(Data!$K:$K,$L30),"") | E30: =IF(AND(ISNUMBER($L30),$L30<>""),IF(INDEX(Data!$L:$L,$L30)="","—",INDEX(Data!$L:$L,$L30)),"") | F30: =IF(AND(ISNUMBER($L30),$L30<>""),IF(INDEX(Data!$M:$M,$L30)="","—",INDEX(Data!$M:$M,$L30)),"") | G30: =IF(AND(ISNUMBER($L30),$L30<>""),IF(INDEX(Data!$N:$N,$L30)="","—",INDEX(Data!$N:$N,$L30)),"") | H30: =IF(AND(ISNUMBER($L30),$L30<>""),IF(INDEX(Data!$Q:$Q,$L30)="","—",INDEX(Data!$Q:$Q,$L30)),"") | I30: =IF(AND(ISNUMBER($L30),$L30<>""),INDEX(Data!$E:$E,$L30),"") | J30: =IF(AND(ISNUMBER($L30),$L30<>""),INDEX(Data!$F:$F,$L30),"") | L30: =IFERROR(MATCH((YEAR($B$3)*10000+MONTH($B$3)*100+DAY($B$3))*1000+21,Data!$W:$W,0),"")
A31: =IF(AND(ISNUMBER($L31),$L31<>""),INDEX(Data!$G:$G,$L31),"") | B31: =IF(AND(ISNUMBER($L31),$L31<>""),IF(INDEX(Data!$I:$I,$L31)="","—",INDEX(Data!$I:$I,$L31)),"") | C31: =IF(AND(ISNUMBER($L31),$L31<>""),INDEX(Data!$J:$J,$L31),"") | D31: =IF(AND(ISNUMBER($L31),$L31<>""),INDEX(Data!$K:$K,$L31),"") | E31: =IF(AND(ISNUMBER($L31),$L31<>""),IF(INDEX(Data!$L:$L,$L31)="","—",INDEX(Data!$L:$L,$L31)),"") | F31: =IF(AND(ISNUMBER($L31),$L31<>""),IF(INDEX(Data!$M:$M,$L31)="","—",INDEX(Data!$M:$M,$L31)),"") | G31: =IF(AND(ISNUMBER($L31),$L31<>""),IF(INDEX(Data!$N:$N,$L31)="","—",INDEX(Data!$N:$N,$L31)),"") | H31: =IF(AND(ISNUMBER($L31),$L31<>""),IF(INDEX(Data!$Q:$Q,$L31)="","—",INDEX(Data!$Q:$Q,$L31)),"") | I31: =IF(AND(ISNUMBER($L31),$L31<>""),INDEX(Data!$E:$E,$L31),"") | J31: =IF(AND(ISNUMBER($L31),$L31<>""),INDEX(Data!$F:$F,$L31),"") | L31: =IFERROR(MATCH((YEAR($B$3)*10000+MONTH($B$3)*100+DAY($B$3))*1000+22,Data!$W:$W,0),"")
A32: =IF(AND(ISNUMBER($L32),$L32<>""),INDEX(Data!$G:$G,$L32),"") | B32: =IF(AND(ISNUMBER($L32),$L32<>""),IF(INDEX(Data!$I:$I,$L32)="","—",INDEX(Data!$I:$I,$L32)),"") | C32: =IF(AND(ISNUMBER($L32),$L32<>""),INDEX(Data!$J:$J,$L32),"") | D32: =IF(AND(ISNUMBER($L32),$L32<>""),INDEX(Data!$K:$K,$L32),"") | E32: =IF(AND(ISNUMBER($L32),$L32<>""),IF(INDEX(Data!$L:$L,$L32)="","—",INDEX(Data!$L:$L,$L32)),"") | F32: =IF(AND(ISNUMBER($L32),$L32<>""),IF(INDEX(Data!$M:$M,$L32)="","—",INDEX(Data!$M:$M,$L32)),"") | G32: =IF(AND(ISNUMBER($L32),$L32<>""),IF(INDEX(Data!$N:$N,$L32)="","—",INDEX(Data!$N:$N,$L32)),"") | H32: =IF(AND(ISNUMBER($L32),$L32<>""),IF(INDEX(Data!$Q:$Q,$L32)="","—",INDEX(Data!$Q:$Q,$L32)),"") | I32: =IF(AND(ISNUMBER($L32),$L32<>""),INDEX(Data!$E:$E,$L32),"") | J32: =IF(AND(ISNUMBER($L32),$L32<>""),INDEX(Data!$F:$F,$L32),"") | L32: =IFERROR(MATCH((YEAR($B$3)*10000+MONTH($B$3)*100+DAY($B$3))*1000+23,Data!$W:$W,0),"")
A33: =IF(AND(ISNUMBER($L33),$L33<>""),INDEX(Data!$G:$G,$L33),"") | B33: =IF(AND(ISNUMBER($L33),$L33<>""),IF(INDEX(Data!$I:$I,$L33)="","—",INDEX(Data!$I:$I,$L33)),"") | C33: =IF(AND(ISNUMBER($L33),$L33<>""),INDEX(Data!$J:$J,$L33),"") | D33: =IF(AND(ISNUMBER($L33),$L33<>""),INDEX(Data!$K:$K,$L33),"") | E33: =IF(AND(ISNUMBER($L33),$L33<>""),IF(INDEX(Data!$L:$L,$L33)="","—",INDEX(Data!$L:$L,$L33)),"") | F33: =IF(AND(ISNUMBER($L33),$L33<>""),IF(INDEX(Data!$M:$M,$L33)="","—",INDEX(Data!$M:$M,$L33)),"") | G33: =IF(AND(ISNUMBER($L33),$L33<>""),IF(INDEX(Data!$N:$N,$L33)="","—",INDEX(Data!$N:$N,$L33)),"") | H33: =IF(AND(ISNUMBER($L33),$L33<>""),IF(INDEX(Data!$Q:$Q,$L33)="","—",INDEX(Data!$Q:$Q,$L33)),"") | I33: =IF(AND(ISNUMBER($L33),$L33<>""),INDEX(Data!$E:$E,$L33),"") | J33: =IF(AND(ISNUMBER($L33),$L33<>""),INDEX(Data!$F:$F,$L33),"") | L33: =IFERROR(MATCH((YEAR($B$3)*10000+MONTH($B$3)*100+DAY($B$3))*1000+24,Data!$W:$W,0),"")
A34: =IF(AND(ISNUMBER($L34),$L34<>""),INDEX(Data!$G:$G,$L34),"") | B34: =IF(AND(ISNUMBER($L34),$L34<>""),IF(INDEX(Data!$I:$I,$L34)="","—",INDEX(Data!$I:$I,$L34)),"") | C34: =IF(AND(ISNUMBER($L34),$L34<>""),INDEX(Data!$J:$J,$L34),"") | D34: =IF(AND(ISNUMBER($L34),$L34<>""),INDEX(Data!$K:$K,$L34),"") | E34: =IF(AND(ISNUMBER($L34),$L34<>""),IF(INDEX(Data!$L:$L,$L34)="","—",INDEX(Data!$L:$L,$L34)),"") | F34: =IF(AND(ISNUMBER($L34),$L34<>""),IF(INDEX(Data!$M:$M,$L34)="","—",INDEX(Data!$M:$M,$L34)),"") | G34: =IF(AND(ISNUMBER($L34),$L34<>""),IF(INDEX(Data!$N:$N,$L34)="","—",INDEX(Data!$N:$N,$L34)),"") | H34: =IF(AND(ISNUMBER($L34),$L34<>""),IF(INDEX(Data!$Q:$Q,$L34)="","—",INDEX(Data!$Q:$Q,$L34)),"") | I34: =IF(AND(ISNUMBER($L34),$L34<>""),INDEX(Data!$E:$E,$L34),"") | J34: =IF(AND(ISNUMBER($L34),$L34<>""),INDEX(Data!$F:$F,$L34),"") | L34: =IFERROR(MATCH((YEAR($B$3)*10000+MONTH($B$3)*100+DAY($B$3))*1000+25,Data!$W:$W,0),"")
A35: =IF(AND(ISNUMBER($L35),$L35<>""),INDEX(Data!$G:$G,$L35),"") | B35: =IF(AND(ISNUMBER($L35),$L35<>""),IF(INDEX(Data!$I:$I,$L35)="","—",INDEX(Data!$I:$I,$L35)),"") | C35: =IF(AND(ISNUMBER($L35),$L35<>""),INDEX(Data!$J:$J,$L35),"") | D35: =IF(AND(ISNUMBER($L35),$L35<>""),INDEX(Data!$K:$K,$L35),"") | E35: =IF(AND(ISNUMBER($L35),$L35<>""),IF(INDEX(Data!$L:$L,$L35)="","—",INDEX(Data!$L:$L,$L35)),"") | F35: =IF(AND(ISNUMBER($L35),$L35<>""),IF(INDEX(Data!$M:$M,$L35)="","—",INDEX(Data!$M:$M,$L35)),"") | G35: =IF(AND(ISNUMBER($L35),$L35<>""),IF(INDEX(Data!$N:$N,$L35)="","—",INDEX(Data!$N:$N,$L35)),"") | H35: =IF(AND(ISNUMBER($L35),$L35<>""),IF(INDEX(Data!$Q:$Q,$L35)="","—",INDEX(Data!$Q:$Q,$L35)),"") | I35: =IF(AND(ISNUMBER($L35),$L35<>""),INDEX(Data!$E:$E,$L35),"") | J35: =IF(AND(ISNUMBER($L35),$L35<>""),INDEX(Data!$F:$F,$L35),"") | L35: =IFERROR(MATCH((YEAR($B$3)*10000+MONTH($B$3)*100+DAY($B$3))*1000+26,Data!$W:$W,0),"")
A36: =IF(AND(ISNUMBER($L36),$L36<>""),INDEX(Data!$G:$G,$L36),"") | B36: =IF(AND(ISNUMBER($L36),$L36<>""),IF(INDEX(Data!$I:$I,$L36)="","—",INDEX(Data!$I:$I,$L36)),"") | C36: =IF(AND(ISNUMBER($L36),$L36<>""),INDEX(Data!$J:$J,$L36),"") | D36: =IF(AND(ISNUMBER($L36),$L36<>""),INDEX(Data!$K:$K,$L36),"") | E36: =IF(AND(ISNUMBER($L36),$L36<>""),IF(INDEX(Data!$L:$L,$L36)="","—",INDEX(Data!$L:$L,$L36)),"") | F36: =IF(AND(ISNUMBER($L36),$L36<>""),IF(INDEX(Data!$M:$M,$L36)="","—",INDEX(Data!$M:$M,$L36)),"") | G36: =IF(AND(ISNUMBER($L36),$L36<>""),IF(INDEX(Data!$N:$N,$L36)="","—",INDEX(Data!$N:$N,$L36)),"") | H36: =IF(AND(ISNUMBER($L36),$L36<>""),IF(INDEX(Data!$Q:$Q,$L36)="","—",INDEX(Data!$Q:$Q,$L36)),"") | I36: =IF(AND(ISNUMBER($L36),$L36<>""),INDEX(Data!$E:$E,$L36),"") | J36: =IF(AND(ISNUMBER($L36),$L36<>""),INDEX(Data!$F:$F,$L36),"") | L36: =IFERROR(MATCH((YEAR($B$3)*10000+MONTH($B$3)*100+DAY($B$3))*1000+27,Data!$W:$W,0),"")
A37: =IF(AND(ISNUMBER($L37),$L37<>""),INDEX(Data!$G:$G,$L37),"") | B37: =IF(AND(ISNUMBER($L37),$L37<>""),IF(INDEX(Data!$I:$I,$L37)="","—",INDEX(Data!$I:$I,$L37)),"") | C37: =IF(AND(ISNUMBER($L37),$L37<>""),INDEX(Data!$J:$J,$L37),"") | D37: =IF(AND(ISNUMBER($L37),$L37<>""),INDEX(Data!$K:$K,$L37),"") | E37: =IF(AND(ISNUMBER($L37),$L37<>""),IF(INDEX(Data!$L:$L,$L37)="","—",INDEX(Data!$L:$L,$L37)),"") | F37: =IF(AND(ISNUMBER($L37),$L37<>""),IF(INDEX(Data!$M:$M,$L37)="","—",INDEX(Data!$M:$M,$L37)),"") | G37: =IF(AND(ISNUMBER($L37),$L37<>""),IF(INDEX(Data!$N:$N,$L37)="","—",INDEX(Data!$N:$N,$L37)),"") | H37: =IF(AND(ISNUMBER($L37),$L37<>""),IF(INDEX(Data!$Q:$Q,$L37)="","—",INDEX(Data!$Q:$Q,$L37)),"") | I37: =IF(AND(ISNUMBER($L37),$L37<>""),INDEX(Data!$E:$E,$L37),"") | J37: =IF(AND(ISNUMBER($L37),$L37<>""),INDEX(Data!$F:$F,$L37),"") | L37: =IFERROR(MATCH((YEAR($B$3)*10000+MONTH($B$3)*100+DAY($B$3))*1000+28,Data!$W:$W,0),"")
A38: =IF(AND(ISNUMBER($L38),$L38<>""),INDEX(Data!$G:$G,$L38),"") | B38: =IF(AND(ISNUMBER($L38),$L38<>""),IF(INDEX(Data!$I:$I,$L38)="","—",INDEX(Data!$I:$I,$L38)),"") | C38: =IF(AND(ISNUMBER($L38),$L38<>""),INDEX(Data!$J:$J,$L38),"") | D38: =IF(AND(ISNUMBER($L38),$L38<>""),INDEX(Data!$K:$K,$L38),"") | E38: =IF(AND(ISNUMBER($L38),$L38<>""),IF(INDEX(Data!$L:$L,$L38)="","—",INDEX(Data!$L:$L,$L38)),"") | F38: =IF(AND(ISNUMBER($L38),$L38<>""),IF(INDEX(Data!$M:$M,$L38)="","—",INDEX(Data!$M:$M,$L38)),"") | G38: =IF(AND(ISNUMBER($L38),$L38<>""),IF(INDEX(Data!$N:$N,$L38)="","—",INDEX(Data!$N:$N,$L38)),"") | H38: =IF(AND(ISNUMBER($L38),$L38<>""),IF(INDEX(Data!$Q:$Q,$L38)="","—",INDEX(Data!$Q:$Q,$L38)),"") | I38: =IF(AND(ISNUMBER($L38),$L38<>""),INDEX(Data!$E:$E,$L38),"") | J38: =IF(AND(ISNUMBER($L38),$L38<>""),INDEX(Data!$F:$F,$L38),"") | L38: =IFERROR(MATCH((YEAR($B$3)*10000+MONTH($B$3)*100+DAY($B$3))*1000+29,Data!$W:$W,0),"")
A39: =IF(AND(ISNUMBER($L39),$L39<>""),INDEX(Data!$G:$G,$L39),"") | B39: =IF(AND(ISNUMBER($L39),$L39<>""),IF(INDEX(Data!$I:$I,$L39)="","—",INDEX(Data!$I:$I,$L39)),"") | C39: =IF(AND(ISNUMBER($L39),$L39<>""),INDEX(Data!$J:$J,$L39),"") | D39: =IF(AND(ISNUMBER($L39),$L39<>""),INDEX(Data!$K:$K,$L39),"") | E39: =IF(AND(ISNUMBER($L39),$L39<>""),IF(INDEX(Data!$L:$L,$L39)="","—",INDEX(Data!$L:$L,$L39)),"") | F39: =IF(AND(ISNUMBER($L39),$L39<>""),IF(INDEX(Data!$M:$M,$L39)="","—",INDEX(Data!$M:$M,$L39)),"") | G39: =IF(AND(ISNUMBER($L39),$L39<>""),IF(INDEX(Data!$N:$N,$L39)="","—",INDEX(Data!$N:$N,$L39)),"") | H39: =IF(AND(ISNUMBER($L39),$L39<>""),IF(INDEX(Data!$Q:$Q,$L39)="","—",INDEX(Data!$Q:$Q,$L39)),"") | I39: =IF(AND(ISNUMBER($L39),$L39<>""),INDEX(Data!$E:$E,$L39),"") | J39: =IF(AND(ISNUMBER($L39),$L39<>""),INDEX(Data!$F:$F,$L39),"") | L39: =IFERROR(MATCH((YEAR($B$3)*10000+MONTH($B$3)*100+DAY($B$3))*1000+30,Data!$W:$W,0),"")
A40: =IF(AND(ISNUMBER($L40),$L40<>""),INDEX(Data!$G:$G,$L40),"") | B40: =IF(AND(ISNUMBER($L40),$L40<>""),IF(INDEX(Data!$I:$I,$L40)="","—",INDEX(Data!$I:$I,$L40)),"") | C40: =IF(AND(ISNUMBER($L40),$L40<>""),INDEX(Data!$J:$J,$L40),"") | D40: =IF(AND(ISNUMBER($L40),$L40<>""),INDEX(Data!$K:$K,$L40),"") | E40: =IF(AND(ISNUMBER($L40),$L40<>""),IF(INDEX(Data!$L:$L,$L40)="","—",INDEX(Data!$L:$L,$L40)),"") | F40: =IF(AND(ISNUMBER($L40),$L40<>""),IF(INDEX(Data!$M:$M,$L40)="","—",INDEX(Data!$M:$M,$L40)),"") | G40: =IF(AND(ISNUMBER($L40),$L40<>""),IF(INDEX(Data!$N:$N,$L40)="","—",INDEX(Data!$N:$N,$L40)),"") | H40: =IF(AND(ISNUMBER($L40),$L40<>""),IF(INDEX(Data!$Q:$Q,$L40)="","—",INDEX(Data!$Q:$Q,$L40)),"") | I40: =IF(AND(ISNUMBER($L40),$L40<>""),INDEX(Data!$E:$E,$L40),"") | J40: =IF(AND(ISNUMBER($L40),$L40<>""),INDEX(Data!$F:$F,$L40),"") | L40: =IFERROR(MATCH((YEAR($B$3)*10000+MONTH($B$3)*100+DAY($B$3))*1000+31,Data!$W:$W,0),"")
A41: =IF(AND(ISNUMBER($L41),$L41<>""),INDEX(Data!$G:$G,$L41),"") | B41: =IF(AND(ISNUMBER($L41),$L41<>""),IF(INDEX(Data!$I:$I,$L41)="","—",INDEX(Data!$I:$I,$L41)),"") | C41: =IF(AND(ISNUMBER($L41),$L41<>""),INDEX(Data!$J:$J,$L41),"") | D41: =IF(AND(ISNUMBER($L41),$L41<>""),INDEX(Data!$K:$K,$L41),"") | E41: =IF(AND(ISNUMBER($L41),$L41<>""),IF(INDEX(Data!$L:$L,$L41)="","—",INDEX(Data!$L:$L,$L41)),"") | F41: =IF(AND(ISNUMBER($L41),$L41<>""),IF(INDEX(Data!$M:$M,$L41)="","—",INDEX(Data!$M:$M,$L41)),"") | G41: =IF(AND(ISNUMBER($L41),$L41<>""),IF(INDEX(Data!$N:$N,$L41)="","—",INDEX(Data!$N:$N,$L41)),"") | H41: =IF(AND(ISNUMBER($L41),$L41<>""),IF(INDEX(Data!$Q:$Q,$L41)="","—",INDEX(Data!$Q:$Q,$L41)),"") | I41: =IF(AND(ISNUMBER($L41),$L41<>""),INDEX(Data!$E:$E,$L41),"") | J41: =IF(AND(ISNUMBER($L41),$L41<>""),INDEX(Data!$F:$F,$L41),"") | L41: =IFERROR(MATCH((YEAR($B$3)*10000+MONTH($B$3)*100+DAY($B$3))*1000+32,Data!$W:$W,0),"")
A42: =IF(AND(ISNUMBER($L42),$L42<>""),INDEX(Data!$G:$G,$L42),"") | B42: =IF(AND(ISNUMBER($L42),$L42<>""),IF(INDEX(Data!$I:$I,$L42)="","—",INDEX(Data!$I:$I,$L42)),"") | C42: =IF(AND(ISNUMBER($L42),$L42<>""),INDEX(Data!$J:$J,$L42),"") | D42: =IF(AND(ISNUMBER($L42),$L42<>""),INDEX(Data!$K:$K,$L42),"") | E42: =IF(AND(ISNUMBER($L42),$L42<>""),IF(INDEX(Data!$L:$L,$L42)="","—",INDEX(Data!$L:$L,$L42)),"") | F42: =IF(AND(ISNUMBER($L42),$L42<>""),IF(INDEX(Data!$M:$M,$L42)="","—",INDEX(Data!$M:$M,$L42)),"") | G42: =IF(AND(ISNUMBER($L42),$L42<>""),IF(INDEX(Data!$N:$N,$L42)="","—",INDEX(Data!$N:$N,$L42)),"") | H42: =IF(AND(ISNUMBER($L42),$L42<>""),IF(INDEX(Data!$Q:$Q,$L42)="","—",INDEX(Data!$Q:$Q,$L42)),"") | I42: =IF(AND(ISNUMBER($L42),$L42<>""),INDEX(Data!$E:$E,$L42),"") | J42: =IF(AND(ISNUMBER($L42),$L42<>""),INDEX(Data!$F:$F,$L42),"") | L42: =IFERROR(MATCH((YEAR($B$3)*10000+MONTH($B$3)*100+DAY($B$3))*1000+33,Data!$W:$W,0),"")
...

Sheet Trends
A1: Cigarette variance by product — last 14 counted days
A2: Sorted by how many days the product disagreed with the POS, then by total. A product off a little every night sits above one that was off a lot once. A dash means no POS sales were loaded for that day.
A4: Product | B4: =IF(Calc!$B$3="","",TEXT(Calc!$B$3,"dd mmm")) | C4: =IF(Calc!$B$4="","",TEXT(Calc!$B$4,"dd mmm")) | D4: =IF(Calc!$B$5="","",TEXT(Calc!$B$5,"dd mmm")) | E4: =IF(Calc!$B$6="","",TEXT(Calc!$B$6,"dd mmm")) | F4: =IF(Calc!$B$7="","",TEXT(Calc!$B$7,"dd mmm")) | G4: =IF(Calc!$B$8="","",TEXT(Calc!$B$8,"dd mmm")) | H4: =IF(Calc!$B$9="","",TEXT(Calc!$B$9,"dd mmm")) | I4: =IF(Calc!$B$10="","",TEXT(Calc!$B$10,"dd mmm")) | J4: =IF(Calc!$B$11="","",TEXT(Calc!$B$11,"dd mmm")) | K4: =IF(Calc!$B$12="","",TEXT(Calc!$B$12,"dd mmm")) | L4: =IF(Calc!$B$13="","",TEXT(Calc!$B$13,"dd mmm")) | M4: =IF(Calc!$B$14="","",TEXT(Calc!$B$14,"dd mmm")) | N4: =IF(Calc!$B$15="","",TEXT(Calc!$B$15,"dd mmm")) | O4: =IF(Calc!$B$16="","",TEXT(Calc!$B$16,"dd mmm")) | P4: Days off | Q4: Total | R4: Worst
A5: =IF(AND(ISNUMBER($T5),$T5<>""),INDEX(Calc!$S$3:$S$122,$T5),"") | B5: =IF(AND(ISNUMBER($T5),$T5<>""),IF(INDEX(Calc!$T$3:$T$122,$T5)="","—",INDEX(Calc!$T$3:$T$122,$T5)),"") | C5: =IF(AND(ISNUMBER($T5),$T5<>""),IF(INDEX(Calc!$U$3:$U$122,$T5)="","—",INDEX(Calc!$U$3:$U$122,$T5)),"") | D5: =IF(AND(ISNUMBER($T5),$T5<>""),IF(INDEX(Calc!$V$3:$V$122,$T5)="","—",INDEX(Calc!$V$3:$V$122,$T5)),"") | E5: =IF(AND(ISNUMBER($T5),$T5<>""),IF(INDEX(Calc!$W$3:$W$122,$T5)="","—",INDEX(Calc!$W$3:$W$122,$T5)),"") | F5: =IF(AND(ISNUMBER($T5),$T5<>""),IF(INDEX(Calc!$X$3:$X$122,$T5)="","—",INDEX(Calc!$X$3:$X$122,$T5)),"") | G5: =IF(AND(ISNUMBER($T5),$T5<>""),IF(INDEX(Calc!$Y$3:$Y$122,$T5)="","—",INDEX(Calc!$Y$3:$Y$122,$T5)),"") | H5: =IF(AND(ISNUMBER($T5),$T5<>""),IF(INDEX(Calc!$Z$3:$Z$122,$T5)="","—",INDEX(Calc!$Z$3:$Z$122,$T5)),"") | I5: =IF(AND(ISNUMBER($T5),$T5<>""),IF(INDEX(Calc!$AA$3:$AA$122,$T5)="","—",INDEX(Calc!$AA$3:$AA$122,$T5)),"") | J5: =IF(AND(ISNUMBER($T5),$T5<>""),IF(INDEX(Calc!$AB$3:$AB$122,$T5)="","—",INDEX(Calc!$AB$3:$AB$122,$T5)),"") | K5: =IF(AND(ISNUMBER($T5),$T5<>""),IF(INDEX(Calc!$AC$3:$AC$122,$T5)="","—",INDEX(Calc!$AC$3:$AC$122,$T5)),"") | L5: =IF(AND(ISNUMBER($T5),$T5<>""),IF(INDEX(Calc!$AD$3:$AD$122,$T5)="","—",INDEX(Calc!$AD$3:$AD$122,$T5)),"") | M5: =IF(AND(ISNUMBER($T5),$T5<>""),IF(INDEX(Calc!$AE$3:$AE$122,$T5)="","—",INDEX(Calc!$AE$3:$AE$122,$T5)),"") | N5: =IF(AND(ISNUMBER($T5),$T5<>""),IF(INDEX(Calc!$AF$3:$AF$122,$T5)="","—",INDEX(Calc!$AF$3:$AF$122,$T5)),"") | O5: =IF(AND(ISNUMBER($T5),$T5<>""),IF(INDEX(Calc!$AG$3:$AG$122,$T5)="","—",INDEX(Calc!$AG$3:$AG$122,$T5)),"") | P5: =IF(AND(ISNUMBER($T5),$T5<>""),IF(INDEX(Calc!$AJ$3:$AJ$122,$T5)="","—",INDEX(Calc!$AJ$3:$AJ$122,$T5)),"") | Q5: =IF(AND(ISNUMBER($T5),$T5<>""),IF(INDEX(Calc!$AK$3:$AK$122,$T5)="","—",INDEX(Calc!$AK$3:$AK$122,$T5)),"") | R5: =IF(AND(ISNUMBER($T5),$T5<>""),IF(INDEX(Calc!$AL$3:$AL$122,$T5)="","—",INDEX(Calc!$AL$3:$AL$122,$T5)),"") | T5: =IFERROR(MATCH(1,Calc!$AN$3:$AN$122,0),"")
A6: =IF(AND(ISNUMBER($T6),$T6<>""),INDEX(Calc!$S$3:$S$122,$T6),"") | B6: =IF(AND(ISNUMBER($T6),$T6<>""),IF(INDEX(Calc!$T$3:$T$122,$T6)="","—",INDEX(Calc!$T$3:$T$122,$T6)),"") | C6: =IF(AND(ISNUMBER($T6),$T6<>""),IF(INDEX(Calc!$U$3:$U$122,$T6)="","—",INDEX(Calc!$U$3:$U$122,$T6)),"") | D6: =IF(AND(ISNUMBER($T6),$T6<>""),IF(INDEX(Calc!$V$3:$V$122,$T6)="","—",INDEX(Calc!$V$3:$V$122,$T6)),"") | E6: =IF(AND(ISNUMBER($T6),$T6<>""),IF(INDEX(Calc!$W$3:$W$122,$T6)="","—",INDEX(Calc!$W$3:$W$122,$T6)),"") | F6: =IF(AND(ISNUMBER($T6),$T6<>""),IF(INDEX(Calc!$X$3:$X$122,$T6)="","—",INDEX(Calc!$X$3:$X$122,$T6)),"") | G6: =IF(AND(ISNUMBER($T6),$T6<>""),IF(INDEX(Calc!$Y$3:$Y$122,$T6)="","—",INDEX(Calc!$Y$3:$Y$122,$T6)),"") | H6: =IF(AND(ISNUMBER($T6),$T6<>""),IF(INDEX(Calc!$Z$3:$Z$122,$T6)="","—",INDEX(Calc!$Z$3:$Z$122,$T6)),"") | I6: =IF(AND(ISNUMBER($T6),$T6<>""),IF(INDEX(Calc!$AA$3:$AA$122,$T6)="","—",INDEX(Calc!$AA$3:$AA$122,$T6)),"") | J6: =IF(AND(ISNUMBER($T6),$T6<>""),IF(INDEX(Calc!$AB$3:$AB$122,$T6)="","—",INDEX(Calc!$AB$3:$AB$122,$T6)),"") | K6: =IF(AND(ISNUMBER($T6),$T6<>""),IF(INDEX(Calc!$AC$3:$AC$122,$T6)="","—",INDEX(Calc!$AC$3:$AC$122,$T6)),"") | L6: =IF(AND(ISNUMBER($T6),$T6<>""),IF(INDEX(Calc!$AD$3:$AD$122,$T6)="","—",INDEX(Calc!$AD$3:$AD$122,$T6)),"") | M6: =IF(AND(ISNUMBER($T6),$T6<>""),IF(INDEX(Calc!$AE$3:$AE$122,$T6)="","—",INDEX(Calc!$AE$3:$AE$122,$T6)),"") | N6: =IF(AND(ISNUMBER($T6),$T6<>""),IF(INDEX(Calc!$AF$3:$AF$122,$T6)="","—",INDEX(Calc!$AF$3:$AF$122,$T6)),"") | O6: =IF(AND(ISNUMBER($T6),$T6<>""),IF(INDEX(Calc!$AG$3:$AG$122,$T6)="","—",INDEX(Calc!$AG$3:$AG$122,$T6)),"") | P6: =IF(AND(ISNUMBER($T6),$T6<>""),IF(INDEX(Calc!$AJ$3:$AJ$122,$T6)="","—",INDEX(Calc!$AJ$3:$AJ$122,$T6)),"") | Q6: =IF(AND(ISNUMBER($T6),$T6<>""),IF(INDEX(Calc!$AK$3:$AK$122,$T6)="","—",INDEX(Calc!$AK$3:$AK$122,$T6)),"") | R6: =IF(AND(ISNUMBER($T6),$T6<>""),IF(INDEX(Calc!$AL$3:$AL$122,$T6)="","—",INDEX(Calc!$AL$3:$AL$122,$T6)),"") | T6: =IFERROR(MATCH(2,Calc!$AN$3:$AN$122,0),"")
A7: =IF(AND(ISNUMBER($T7),$T7<>""),INDEX(Calc!$S$3:$S$122,$T7),"") | B7: =IF(AND(ISNUMBER($T7),$T7<>""),IF(INDEX(Calc!$T$3:$T$122,$T7)="","—",INDEX(Calc!$T$3:$T$122,$T7)),"") | C7: =IF(AND(ISNUMBER($T7),$T7<>""),IF(INDEX(Calc!$U$3:$U$122,$T7)="","—",INDEX(Calc!$U$3:$U$122,$T7)),"") | D7: =IF(AND(ISNUMBER($T7),$T7<>""),IF(INDEX(Calc!$V$3:$V$122,$T7)="","—",INDEX(Calc!$V$3:$V$122,$T7)),"") | E7: =IF(AND(ISNUMBER($T7),$T7<>""),IF(INDEX(Calc!$W$3:$W$122,$T7)="","—",INDEX(Calc!$W$3:$W$122,$T7)),"") | F7: =IF(AND(ISNUMBER($T7),$T7<>""),IF(INDEX(Calc!$X$3:$X$122,$T7)="","—",INDEX(Calc!$X$3:$X$122,$T7)),"") | G7: =IF(AND(ISNUMBER($T7),$T7<>""),IF(INDEX(Calc!$Y$3:$Y$122,$T7)="","—",INDEX(Calc!$Y$3:$Y$122,$T7)),"") | H7: =IF(AND(ISNUMBER($T7),$T7<>""),IF(INDEX(Calc!$Z$3:$Z$122,$T7)="","—",INDEX(Calc!$Z$3:$Z$122,$T7)),"") | I7: =IF(AND(ISNUMBER($T7),$T7<>""),IF(INDEX(Calc!$AA$3:$AA$122,$T7)="","—",INDEX(Calc!$AA$3:$AA$122,$T7)),"") | J7: =IF(AND(ISNUMBER($T7),$T7<>""),IF(INDEX(Calc!$AB$3:$AB$122,$T7)="","—",INDEX(Calc!$AB$3:$AB$122,$T7)),"") | K7: =IF(AND(ISNUMBER($T7),$T7<>""),IF(INDEX(Calc!$AC$3:$AC$122,$T7)="","—",INDEX(Calc!$AC$3:$AC$122,$T7)),"") | L7: =IF(AND(ISNUMBER($T7),$T7<>""),IF(INDEX(Calc!$AD$3:$AD$122,$T7)="","—",INDEX(Calc!$AD$3:$AD$122,$T7)),"") | M7: =IF(AND(ISNUMBER($T7),$T7<>""),IF(INDEX(Calc!$AE$3:$AE$122,$T7)="","—",INDEX(Calc!$AE$3:$AE$122,$T7)),"") | N7: =IF(AND(ISNUMBER($T7),$T7<>""),IF(INDEX(Calc!$AF$3:$AF$122,$T7)="","—",INDEX(Calc!$AF$3:$AF$122,$T7)),"") | O7: =IF(AND(ISNUMBER($T7),$T7<>""),IF(INDEX(Calc!$AG$3:$AG$122,$T7)="","—",INDEX(Calc!$AG$3:$AG$122,$T7)),"") | P7: =IF(AND(ISNUMBER($T7),$T7<>""),IF(INDEX(Calc!$AJ$3:$AJ$122,$T7)="","—",INDEX(Calc!$AJ$3:$AJ$122,$T7)),"") | Q7: =IF(AND(ISNUMBER($T7),$T7<>""),IF(INDEX(Calc!$AK$3:$AK$122,$T7)="","—",INDEX(Calc!$AK$3:$AK$122,$T7)),"") | R7: =IF(AND(ISNUMBER($T7),$T7<>""),IF(INDEX(Calc!$AL$3:$AL$122,$T7)="","—",INDEX(Calc!$AL$3:$AL$122,$T7)),"") | T7: =IFERROR(MATCH(3,Calc!$AN$3:$AN$122,0),"")
A8: =IF(AND(ISNUMBER($T8),$T8<>""),INDEX(Calc!$S$3:$S$122,$T8),"") | B8: =IF(AND(ISNUMBER($T8),$T8<>""),IF(INDEX(Calc!$T$3:$T$122,$T8)="","—",INDEX(Calc!$T$3:$T$122,$T8)),"") | C8: =IF(AND(ISNUMBER($T8),$T8<>""),IF(INDEX(Calc!$U$3:$U$122,$T8)="","—",INDEX(Calc!$U$3:$U$122,$T8)),"") | D8: =IF(AND(ISNUMBER($T8),$T8<>""),IF(INDEX(Calc!$V$3:$V$122,$T8)="","—",INDEX(Calc!$V$3:$V$122,$T8)),"") | E8: =IF(AND(ISNUMBER($T8),$T8<>""),IF(INDEX(Calc!$W$3:$W$122,$T8)="","—",INDEX(Calc!$W$3:$W$122,$T8)),"") | F8: =IF(AND(ISNUMBER($T8),$T8<>""),IF(INDEX(Calc!$X$3:$X$122,$T8)="","—",INDEX(Calc!$X$3:$X$122,$T8)),"") | G8: =IF(AND(ISNUMBER($T8),$T8<>""),IF(INDEX(Calc!$Y$3:$Y$122,$T8)="","—",INDEX(Calc!$Y$3:$Y$122,$T8)),"") | H8: =IF(AND(ISNUMBER($T8),$T8<>""),IF(INDEX(Calc!$Z$3:$Z$122,$T8)="","—",INDEX(Calc!$Z$3:$Z$122,$T8)),"") | I8: =IF(AND(ISNUMBER($T8),$T8<>""),IF(INDEX(Calc!$AA$3:$AA$122,$T8)="","—",INDEX(Calc!$AA$3:$AA$122,$T8)),"") | J8: =IF(AND(ISNUMBER($T8),$T8<>""),IF(INDEX(Calc!$AB$3:$AB$122,$T8)="","—",INDEX(Calc!$AB$3:$AB$122,$T8)),"") | K8: =IF(AND(ISNUMBER($T8),$T8<>""),IF(INDEX(Calc!$AC$3:$AC$122,$T8)="","—",INDEX(Calc!$AC$3:$AC$122,$T8)),"") | L8: =IF(AND(ISNUMBER($T8),$T8<>""),IF(INDEX(Calc!$AD$3:$AD$122,$T8)="","—",INDEX(Calc!$AD$3:$AD$122,$T8)),"") | M8: =IF(AND(ISNUMBER($T8),$T8<>""),IF(INDEX(Calc!$AE$3:$AE$122,$T8)="","—",INDEX(Calc!$AE$3:$AE$122,$T8)),"") | N8: =IF(AND(ISNUMBER($T8),$T8<>""),IF(INDEX(Calc!$AF$3:$AF$122,$T8)="","—",INDEX(Calc!$AF$3:$AF$122,$T8)),"") | O8: =IF(AND(ISNUMBER($T8),$T8<>""),IF(INDEX(Calc!$AG$3:$AG$122,$T8)="","—",INDEX(Calc!$AG$3:$AG$122,$T8)),"") | P8: =IF(AND(ISNUMBER($T8),$T8<>""),IF(INDEX(Calc!$AJ$3:$AJ$122,$T8)="","—",INDEX(Calc!$AJ$3:$AJ$122,$T8)),"") | Q8: =IF(AND(ISNUMBER($T8),$T8<>""),IF(INDEX(Calc!$AK$3:$AK$122,$T8)="","—",INDEX(Calc!$AK$3:$AK$122,$T8)),"") | R8: =IF(AND(ISNUMBER($T8),$T8<>""),IF(INDEX(Calc!$AL$3:$AL$122,$T8)="","—",INDEX(Calc!$AL$3:$AL$122,$T8)),"") | T8: =IFERROR(MATCH(4,Calc!$AN$3:$AN$122,0),"")
A9: =IF(AND(ISNUMBER($T9),$T9<>""),INDEX(Calc!$S$3:$S$122,$T9),"") | B9: =IF(AND(ISNUMBER($T9),$T9<>""),IF(INDEX(Calc!$T$3:$T$122,$T9)="","—",INDEX(Calc!$T$3:$T$122,$T9)),"") | C9: =IF(AND(ISNUMBER($T9),$T9<>""),IF(INDEX(Calc!$U$3:$U$122,$T9)="","—",INDEX(Calc!$U$3:$U$122,$T9)),"") | D9: =IF(AND(ISNUMBER($T9),$T9<>""),IF(INDEX(Calc!$V$3:$V$122,$T9)="","—",INDEX(Calc!$V$3:$V$122,$T9)),"") | E9: =IF(AND(ISNUMBER($T9),$T9<>""),IF(INDEX(Calc!$W$3:$W$122,$T9)="","—",INDEX(Calc!$W$3:$W$122,$T9)),"") | F9: =IF(AND(ISNUMBER($T9),$T9<>""),IF(INDEX(Calc!$X$3:$X$122,$T9)="","—",INDEX(Calc!$X$3:$X$122,$T9)),"") | G9: =IF(AND(ISNUMBER($T9),$T9<>""),IF(INDEX(Calc!$Y$3:$Y$122,$T9)="","—",INDEX(Calc!$Y$3:$Y$122,$T9)),"") | H9: =IF(AND(ISNUMBER($T9),$T9<>""),IF(INDEX(Calc!$Z$3:$Z$122,$T9)="","—",INDEX(Calc!$Z$3:$Z$122,$T9)),"") | I9: =IF(AND(ISNUMBER($T9),$T9<>""),IF(INDEX(Calc!$AA$3:$AA$122,$T9)="","—",INDEX(Calc!$AA$3:$AA$122,$T9)),"") | J9: =IF(AND(ISNUMBER($T9),$T9<>""),IF(INDEX(Calc!$AB$3:$AB$122,$T9)="","—",INDEX(Calc!$AB$3:$AB$122,$T9)),"") | K9: =IF(AND(ISNUMBER($T9),$T9<>""),IF(INDEX(Calc!$AC$3:$AC$122,$T9)="","—",INDEX(Calc!$AC$3:$AC$122,$T9)),"") | L9: =IF(AND(ISNUMBER($T9),$T9<>""),IF(INDEX(Calc!$AD$3:$AD$122,$T9)="","—",INDEX(Calc!$AD$3:$AD$122,$T9)),"") | M9: =IF(AND(ISNUMBER($T9),$T9<>""),IF(INDEX(Calc!$AE$3:$AE$122,$T9)="","—",INDEX(Calc!$AE$3:$AE$122,$T9)),"") | N9: =IF(AND(ISNUMBER($T9),$T9<>""),IF(INDEX(Calc!$AF$3:$AF$122,$T9)="","—",INDEX(Calc!$AF$3:$AF$122,$T9)),"") | O9: =IF(AND(ISNUMBER($T9),$T9<>""),IF(INDEX(Calc!$AG$3:$AG$122,$T9)="","—",INDEX(Calc!$AG$3:$AG$122,$T9)),"") | P9: =IF(AND(ISNUMBER($T9),$T9<>""),IF(INDEX(Calc!$AJ$3:$AJ$122,$T9)="","—",INDEX(Calc!$AJ$3:$AJ$122,$T9)),"") | Q9: =IF(AND(ISNUMBER($T9),$T9<>""),IF(INDEX(Calc!$AK$3:$AK$122,$T9)="","—",INDEX(Calc!$AK$3:$AK$122,$T9)),"") | R9: =IF(AND(ISNUMBER($T9),$T9<>""),IF(INDEX(Calc!$AL$3:$AL$122,$T9)="","—",INDEX(Calc!$AL$3:$AL$122,$T9)),"") | T9: =IFERROR(MATCH(5,Calc!$AN$3:$AN$122,0),"")
A10: =IF(AND(ISNUMBER($T10),$T10<>""),INDEX(Calc!$S$3:$S$122,$T10),"") | B10: =IF(AND(ISNUMBER($T10),$T10<>""),IF(INDEX(Calc!$T$3:$T$122,$T10)="","—",INDEX(Calc!$T$3:$T$122,$T10)),"") | C10: =IF(AND(ISNUMBER($T10),$T10<>""),IF(INDEX(Calc!$U$3:$U$122,$T10)="","—",INDEX(Calc!$U$3:$U$122,$T10)),"") | D10: =IF(AND(ISNUMBER($T10),$T10<>""),IF(INDEX(Calc!$V$3:$V$122,$T10)="","—",INDEX(Calc!$V$3:$V$122,$T10)),"") | E10: =IF(AND(ISNUMBER($T10),$T10<>""),IF(INDEX(Calc!$W$3:$W$122,$T10)="","—",INDEX(Calc!$W$3:$W$122,$T10)),"") | F10: =IF(AND(ISNUMBER($T10),$T10<>""),IF(INDEX(Calc!$X$3:$X$122,$T10)="","—",INDEX(Calc!$X$3:$X$122,$T10)),"") | G10: =IF(AND(ISNUMBER($T10),$T10<>""),IF(INDEX(Calc!$Y$3:$Y$122,$T10)="","—",INDEX(Calc!$Y$3:$Y$122,$T10)),"") | H10: =IF(AND(ISNUMBER($T10),$T10<>""),IF(INDEX(Calc!$Z$3:$Z$122,$T10)="","—",INDEX(Calc!$Z$3:$Z$122,$T10)),"") | I10: =IF(AND(ISNUMBER($T10),$T10<>""),IF(INDEX(Calc!$AA$3:$AA$122,$T10)="","—",INDEX(Calc!$AA$3:$AA$122,$T10)),"") | J10: =IF(AND(ISNUMBER($T10),$T10<>""),IF(INDEX(Calc!$AB$3:$AB$122,$T10)="","—",INDEX(Calc!$AB$3:$AB$122,$T10)),"") | K10: =IF(AND(ISNUMBER($T10),$T10<>""),IF(INDEX(Calc!$AC$3:$AC$122,$T10)="","—",INDEX(Calc!$AC$3:$AC$122,$T10)),"") | L10: =IF(AND(ISNUMBER($T10),$T10<>""),IF(INDEX(Calc!$AD$3:$AD$122,$T10)="","—",INDEX(Calc!$AD$3:$AD$122,$T10)),"") | M10: =IF(AND(ISNUMBER($T10),$T10<>""),IF(INDEX(Calc!$AE$3:$AE$122,$T10)="","—",INDEX(Calc!$AE$3:$AE$122,$T10)),"") | N10: =IF(AND(ISNUMBER($T10),$T10<>""),IF(INDEX(Calc!$AF$3:$AF$122,$T10)="","—",INDEX(Calc!$AF$3:$AF$122,$T10)),"") | O10: =IF(AND(ISNUMBER($T10),$T10<>""),IF(INDEX(Calc!$AG$3:$AG$122,$T10)="","—",INDEX(Calc!$AG$3:$AG$122,$T10)),"") | P10: =IF(AND(ISNUMBER($T10),$T10<>""),IF(INDEX(Calc!$AJ$3:$AJ$122,$T10)="","—",INDEX(Calc!$AJ$3:$AJ$122,$T10)),"") | Q10: =IF(AND(ISNUMBER($T10),$T10<>""),IF(INDEX(Calc!$AK$3:$AK$122,$T10)="","—",INDEX(Calc!$AK$3:$AK$122,$T10)),"") | R10: =IF(AND(ISNUMBER($T10),$T10<>""),IF(INDEX(Calc!$AL$3:$AL$122,$T10)="","—",INDEX(Calc!$AL$3:$AL$122,$T10)),"") | T10: =IFERROR(MATCH(6,Calc!$AN$3:$AN$122,0),"")
A11: =IF(AND(ISNUMBER($T11),$T11<>""),INDEX(Calc!$S$3:$S$122,$T11),"") | B11: =IF(AND(ISNUMBER($T11),$T11<>""),IF(INDEX(Calc!$T$3:$T$122,$T11)="","—",INDEX(Calc!$T$3:$T$122,$T11)),"") | C11: =IF(AND(ISNUMBER($T11),$T11<>""),IF(INDEX(Calc!$U$3:$U$122,$T11)="","—",INDEX(Calc!$U$3:$U$122,$T11)),"") | D11: =IF(AND(ISNUMBER($T11),$T11<>""),IF(INDEX(Calc!$V$3:$V$122,$T11)="","—",INDEX(Calc!$V$3:$V$122,$T11)),"") | E11: =IF(AND(ISNUMBER($T11),$T11<>""),IF(INDEX(Calc!$W$3:$W$122,$T11)="","—",INDEX(Calc!$W$3:$W$122,$T11)),"") | F11: =IF(AND(ISNUMBER($T11),$T11<>""),IF(INDEX(Calc!$X$3:$X$122,$T11)="","—",INDEX(Calc!$X$3:$X$122,$T11)),"") | G11: =IF(AND(ISNUMBER($T11),$T11<>""),IF(INDEX(Calc!$Y$3:$Y$122,$T11)="","—",INDEX(Calc!$Y$3:$Y$122,$T11)),"") | H11: =IF(AND(ISNUMBER($T11),$T11<>""),IF(INDEX(Calc!$Z$3:$Z$122,$T11)="","—",INDEX(Calc!$Z$3:$Z$122,$T11)),"") | I11: =IF(AND(ISNUMBER($T11),$T11<>""),IF(INDEX(Calc!$AA$3:$AA$122,$T11)="","—",INDEX(Calc!$AA$3:$AA$122,$T11)),"") | J11: =IF(AND(ISNUMBER($T11),$T11<>""),IF(INDEX(Calc!$AB$3:$AB$122,$T11)="","—",INDEX(Calc!$AB$3:$AB$122,$T11)),"") | K11: =IF(AND(ISNUMBER($T11),$T11<>""),IF(INDEX(Calc!$AC$3:$AC$122,$T11)="","—",INDEX(Calc!$AC$3:$AC$122,$T11)),"") | L11: =IF(AND(ISNUMBER($T11),$T11<>""),IF(INDEX(Calc!$AD$3:$AD$122,$T11)="","—",INDEX(Calc!$AD$3:$AD$122,$T11)),"") | M11: =IF(AND(ISNUMBER($T11),$T11<>""),IF(INDEX(Calc!$AE$3:$AE$122,$T11)="","—",INDEX(Calc!$AE$3:$AE$122,$T11)),"") | N11: =IF(AND(ISNUMBER($T11),$T11<>""),IF(INDEX(Calc!$AF$3:$AF$122,$T11)="","—",INDEX(Calc!$AF$3:$AF$122,$T11)),"") | O11: =IF(AND(ISNUMBER($T11),$T11<>""),IF(INDEX(Calc!$AG$3:$AG$122,$T11)="","—",INDEX(Calc!$AG$3:$AG$122,$T11)),"") | P11: =IF(AND(ISNUMBER($T11),$T11<>""),IF(INDEX(Calc!$AJ$3:$AJ$122,$T11)="","—",INDEX(Calc!$AJ$3:$AJ$122,$T11)),"") | Q11: =IF(AND(ISNUMBER($T11),$T11<>""),IF(INDEX(Calc!$AK$3:$AK$122,$T11)="","—",INDEX(Calc!$AK$3:$AK$122,$T11)),"") | R11: =IF(AND(ISNUMBER($T11),$T11<>""),IF(INDEX(Calc!$AL$3:$AL$122,$T11)="","—",INDEX(Calc!$AL$3:$AL$122,$T11)),"") | T11: =IFERROR(MATCH(7,Calc!$AN$3:$AN$122,0),"")
A12: =IF(AND(ISNUMBER($T12),$T12<>""),INDEX(Calc!$S$3:$S$122,$T12),"") | B12: =IF(AND(ISNUMBER($T12),$T12<>""),IF(INDEX(Calc!$T$3:$T$122,$T12)="","—",INDEX(Calc!$T$3:$T$122,$T12)),"") | C12: =IF(AND(ISNUMBER($T12),$T12<>""),IF(INDEX(Calc!$U$3:$U$122,$T12)="","—",INDEX(Calc!$U$3:$U$122,$T12)),"") | D12: =IF(AND(ISNUMBER($T12),$T12<>""),IF(INDEX(Calc!$V$3:$V$122,$T12)="","—",INDEX(Calc!$V$3:$V$122,$T12)),"") | E12: =IF(AND(ISNUMBER($T12),$T12<>""),IF(INDEX(Calc!$W$3:$W$122,$T12)="","—",INDEX(Calc!$W$3:$W$122,$T12)),"") | F12: =IF(AND(ISNUMBER($T12),$T12<>""),IF(INDEX(Calc!$X$3:$X$122,$T12)="","—",INDEX(Calc!$X$3:$X$122,$T12)),"") | G12: =IF(AND(ISNUMBER($T12),$T12<>""),IF(INDEX(Calc!$Y$3:$Y$122,$T12)="","—",INDEX(Calc!$Y$3:$Y$122,$T12)),"") | H12: =IF(AND(ISNUMBER($T12),$T12<>""),IF(INDEX(Calc!$Z$3:$Z$122,$T12)="","—",INDEX(Calc!$Z$3:$Z$122,$T12)),"") | I12: =IF(AND(ISNUMBER($T12),$T12<>""),IF(INDEX(Calc!$AA$3:$AA$122,$T12)="","—",INDEX(Calc!$AA$3:$AA$122,$T12)),"") | J12: =IF(AND(ISNUMBER($T12),$T12<>""),IF(INDEX(Calc!$AB$3:$AB$122,$T12)="","—",INDEX(Calc!$AB$3:$AB$122,$T12)),"") | K12: =IF(AND(ISNUMBER($T12),$T12<>""),IF(INDEX(Calc!$AC$3:$AC$122,$T12)="","—",INDEX(Calc!$AC$3:$AC$122,$T12)),"") | L12: =IF(AND(ISNUMBER($T12),$T12<>""),IF(INDEX(Calc!$AD$3:$AD$122,$T12)="","—",INDEX(Calc!$AD$3:$AD$122,$T12)),"") | M12: =IF(AND(ISNUMBER($T12),$T12<>""),IF(INDEX(Calc!$AE$3:$AE$122,$T12)="","—",INDEX(Calc!$AE$3:$AE$122,$T12)),"") | N12: =IF(AND(ISNUMBER($T12),$T12<>""),IF(INDEX(Calc!$AF$3:$AF$122,$T12)="","—",INDEX(Calc!$AF$3:$AF$122,$T12)),"") | O12: =IF(AND(ISNUMBER($T12),$T12<>""),IF(INDEX(Calc!$AG$3:$AG$122,$T12)="","—",INDEX(Calc!$AG$3:$AG$122,$T12)),"") | P12: =IF(AND(ISNUMBER($T12),$T12<>""),IF(INDEX(Calc!$AJ$3:$AJ$122,$T12)="","—",INDEX(Calc!$AJ$3:$AJ$122,$T12)),"") | Q12: =IF(AND(ISNUMBER($T12),$T12<>""),IF(INDEX(Calc!$AK$3:$AK$122,$T12)="","—",INDEX(Calc!$AK$3:$AK$122,$T12)),"") | R12: =IF(AND(ISNUMBER($T12),$T12<>""),IF(INDEX(Calc!$AL$3:$AL$122,$T12)="","—",INDEX(Calc!$AL$3:$AL$122,$T12)),"") | T12: =IFERROR(MATCH(8,Calc!$AN$3:$AN$122,0),"")
A13: =IF(AND(ISNUMBER($T13),$T13<>""),INDEX(Calc!$S$3:$S$122,$T13),"") | B13: =IF(AND(ISNUMBER($T13),$T13<>""),IF(INDEX(Calc!$T$3:$T$122,$T13)="","—",INDEX(Calc!$T$3:$T$122,$T13)),"") | C13: =IF(AND(ISNUMBER($T13),$T13<>""),IF(INDEX(Calc!$U$3:$U$122,$T13)="","—",INDEX(Calc!$U$3:$U$122,$T13)),"") | D13: =IF(AND(ISNUMBER($T13),$T13<>""),IF(INDEX(Calc!$V$3:$V$122,$T13)="","—",INDEX(Calc!$V$3:$V$122,$T13)),"") | E13: =IF(AND(ISNUMBER($T13),$T13<>""),IF(INDEX(Calc!$W$3:$W$122,$T13)="","—",INDEX(Calc!$W$3:$W$122,$T13)),"") | F13: =IF(AND(ISNUMBER($T13),$T13<>""),IF(INDEX(Calc!$X$3:$X$122,$T13)="","—",INDEX(Calc!$X$3:$X$122,$T13)),"") | G13: =IF(AND(ISNUMBER($T13),$T13<>""),IF(INDEX(Calc!$Y$3:$Y$122,$T13)="","—",INDEX(Calc!$Y$3:$Y$122,$T13)),"") | H13: =IF(AND(ISNUMBER($T13),$T13<>""),IF(INDEX(Calc!$Z$3:$Z$122,$T13)="","—",INDEX(Calc!$Z$3:$Z$122,$T13)),"") | I13: =IF(AND(ISNUMBER($T13),$T13<>""),IF(INDEX(Calc!$AA$3:$AA$122,$T13)="","—",INDEX(Calc!$AA$3:$AA$122,$T13)),"") | J13: =IF(AND(ISNUMBER($T13),$T13<>""),IF(INDEX(Calc!$AB$3:$AB$122,$T13)="","—",INDEX(Calc!$AB$3:$AB$122,$T13)),"") | K13: =IF(AND(ISNUMBER($T13),$T13<>""),IF(INDEX(Calc!$AC$3:$AC$122,$T13)="","—",INDEX(Calc!$AC$3:$AC$122,$T13)),"") | L13: =IF(AND(ISNUMBER($T13),$T13<>""),IF(INDEX(Calc!$AD$3:$AD$122,$T13)="","—",INDEX(Calc!$AD$3:$AD$122,$T13)),"") | M13: =IF(AND(ISNUMBER($T13),$T13<>""),IF(INDEX(Calc!$AE$3:$AE$122,$T13)="","—",INDEX(Calc!$AE$3:$AE$122,$T13)),"") | N13: =IF(AND(ISNUMBER($T13),$T13<>""),IF(INDEX(Calc!$AF$3:$AF$122,$T13)="","—",INDEX(Calc!$AF$3:$AF$122,$T13)),"") | O13: =IF(AND(ISNUMBER($T13),$T13<>""),IF(INDEX(Calc!$AG$3:$AG$122,$T13)="","—",INDEX(Calc!$AG$3:$AG$122,$T13)),"") | P13: =IF(AND(ISNUMBER($T13),$T13<>""),IF(INDEX(Calc!$AJ$3:$AJ$122,$T13)="","—",INDEX(Calc!$AJ$3:$AJ$122,$T13)),"") | Q13: =IF(AND(ISNUMBER($T13),$T13<>""),IF(INDEX(Calc!$AK$3:$AK$122,$T13)="","—",INDEX(Calc!$AK$3:$AK$122,$T13)),"") | R13: =IF(AND(ISNUMBER($T13),$T13<>""),IF(INDEX(Calc!$AL$3:$AL$122,$T13)="","—",INDEX(Calc!$AL$3:$AL$122,$T13)),"") | T13: =IFERROR(MATCH(9,Calc!$AN$3:$AN$122,0),"")
A14: =IF(AND(ISNUMBER($T14),$T14<>""),INDEX(Calc!$S$3:$S$122,$T14),"") | B14: =IF(AND(ISNUMBER($T14),$T14<>""),IF(INDEX(Calc!$T$3:$T$122,$T14)="","—",INDEX(Calc!$T$3:$T$122,$T14)),"") | C14: =IF(AND(ISNUMBER($T14),$T14<>""),IF(INDEX(Calc!$U$3:$U$122,$T14)="","—",INDEX(Calc!$U$3:$U$122,$T14)),"") | D14: =IF(AND(ISNUMBER($T14),$T14<>""),IF(INDEX(Calc!$V$3:$V$122,$T14)="","—",INDEX(Calc!$V$3:$V$122,$T14)),"") | E14: =IF(AND(ISNUMBER($T14),$T14<>""),IF(INDEX(Calc!$W$3:$W$122,$T14)="","—",INDEX(Calc!$W$3:$W$122,$T14)),"") | F14: =IF(AND(ISNUMBER($T14),$T14<>""),IF(INDEX(Calc!$X$3:$X$122,$T14)="","—",INDEX(Calc!$X$3:$X$122,$T14)),"") | G14: =IF(AND(ISNUMBER($T14),$T14<>""),IF(INDEX(Calc!$Y$3:$Y$122,$T14)="","—",INDEX(Calc!$Y$3:$Y$122,$T14)),"") | H14: =IF(AND(ISNUMBER($T14),$T14<>""),IF(INDEX(Calc!$Z$3:$Z$122,$T14)="","—",INDEX(Calc!$Z$3:$Z$122,$T14)),"") | I14: =IF(AND(ISNUMBER($T14),$T14<>""),IF(INDEX(Calc!$AA$3:$AA$122,$T14)="","—",INDEX(Calc!$AA$3:$AA$122,$T14)),"") | J14: =IF(AND(ISNUMBER($T14),$T14<>""),IF(INDEX(Calc!$AB$3:$AB$122,$T14)="","—",INDEX(Calc!$AB$3:$AB$122,$T14)),"") | K14: =IF(AND(ISNUMBER($T14),$T14<>""),IF(INDEX(Calc!$AC$3:$AC$122,$T14)="","—",INDEX(Calc!$AC$3:$AC$122,$T14)),"") | L14: =IF(AND(ISNUMBER($T14),$T14<>""),IF(INDEX(Calc!$AD$3:$AD$122,$T14)="","—",INDEX(Calc!$AD$3:$AD$122,$T14)),"") | M14: =IF(AND(ISNUMBER($T14),$T14<>""),IF(INDEX(Calc!$AE$3:$AE$122,$T14)="","—",INDEX(Calc!$AE$3:$AE$122,$T14)),"") | N14: =IF(AND(ISNUMBER($T14),$T14<>""),IF(INDEX(Calc!$AF$3:$AF$122,$T14)="","—",INDEX(Calc!$AF$3:$AF$122,$T14)),"") | O14: =IF(AND(ISNUMBER($T14),$T14<>""),IF(INDEX(Calc!$AG$3:$AG$122,$T14)="","—",INDEX(Calc!$AG$3:$AG$122,$T14)),"") | P14: =IF(AND(ISNUMBER($T14),$T14<>""),IF(INDEX(Calc!$AJ$3:$AJ$122,$T14)="","—",INDEX(Calc!$AJ$3:$AJ$122,$T14)),"") | Q14: =IF(AND(ISNUMBER($T14),$T14<>""),IF(INDEX(Calc!$AK$3:$AK$122,$T14)="","—",INDEX(Calc!$AK$3:$AK$122,$T14)),"") | R14: =IF(AND(ISNUMBER($T14),$T14<>""),IF(INDEX(Calc!$AL$3:$AL$122,$T14)="","—",INDEX(Calc!$AL$3:$AL$122,$T14)),"") | T14: =IFERROR(MATCH(10,Calc!$AN$3:$AN$122,0),"")
A15: =IF(AND(ISNUMBER($T15),$T15<>""),INDEX(Calc!$S$3:$S$122,$T15),"") | B15: =IF(AND(ISNUMBER($T15),$T15<>""),IF(INDEX(Calc!$T$3:$T$122,$T15)="","—",INDEX(Calc!$T$3:$T$122,$T15)),"") | C15: =IF(AND(ISNUMBER($T15),$T15<>""),IF(INDEX(Calc!$U$3:$U$122,$T15)="","—",INDEX(Calc!$U$3:$U$122,$T15)),"") | D15: =IF(AND(ISNUMBER($T15),$T15<>""),IF(INDEX(Calc!$V$3:$V$122,$T15)="","—",INDEX(Calc!$V$3:$V$122,$T15)),"") | E15: =IF(AND(ISNUMBER($T15),$T15<>""),IF(INDEX(Calc!$W$3:$W$122,$T15)="","—",INDEX(Calc!$W$3:$W$122,$T15)),"") | F15: =IF(AND(ISNUMBER($T15),$T15<>""),IF(INDEX(Calc!$X$3:$X$122,$T15)="","—",INDEX(Calc!$X$3:$X$122,$T15)),"") | G15: =IF(AND(ISNUMBER($T15),$T15<>""),IF(INDEX(Calc!$Y$3:$Y$122,$T15)="","—",INDEX(Calc!$Y$3:$Y$122,$T15)),"") | H15: =IF(AND(ISNUMBER($T15),$T15<>""),IF(INDEX(Calc!$Z$3:$Z$122,$T15)="","—",INDEX(Calc!$Z$3:$Z$122,$T15)),"") | I15: =IF(AND(ISNUMBER($T15),$T15<>""),IF(INDEX(Calc!$AA$3:$AA$122,$T15)="","—",INDEX(Calc!$AA$3:$AA$122,$T15)),"") | J15: =IF(AND(ISNUMBER($T15),$T15<>""),IF(INDEX(Calc!$AB$3:$AB$122,$T15)="","—",INDEX(Calc!$AB$3:$AB$122,$T15)),"") | K15: =IF(AND(ISNUMBER($T15),$T15<>""),IF(INDEX(Calc!$AC$3:$AC$122,$T15)="","—",INDEX(Calc!$AC$3:$AC$122,$T15)),"") | L15: =IF(AND(ISNUMBER($T15),$T15<>""),IF(INDEX(Calc!$AD$3:$AD$122,$T15)="","—",INDEX(Calc!$AD$3:$AD$122,$T15)),"") | M15: =IF(AND(ISNUMBER($T15),$T15<>""),IF(INDEX(Calc!$AE$3:$AE$122,$T15)="","—",INDEX(Calc!$AE$3:$AE$122,$T15)),"") | N15: =IF(AND(ISNUMBER($T15),$T15<>""),IF(INDEX(Calc!$AF$3:$AF$122,$T15)="","—",INDEX(Calc!$AF$3:$AF$122,$T15)),"") | O15: =IF(AND(ISNUMBER($T15),$T15<>""),IF(INDEX(Calc!$AG$3:$AG$122,$T15)="","—",INDEX(Calc!$AG$3:$AG$122,$T15)),"") | P15: =IF(AND(ISNUMBER($T15),$T15<>""),IF(INDEX(Calc!$AJ$3:$AJ$122,$T15)="","—",INDEX(Calc!$AJ$3:$AJ$122,$T15)),"") | Q15: =IF(AND(ISNUMBER($T15),$T15<>""),IF(INDEX(Calc!$AK$3:$AK$122,$T15)="","—",INDEX(Calc!$AK$3:$AK$122,$T15)),"") | R15: =IF(AND(ISNUMBER($T15),$T15<>""),IF(INDEX(Calc!$AL$3:$AL$122,$T15)="","—",INDEX(Calc!$AL$3:$AL$122,$T15)),"") | T15: =IFERROR(MATCH(11,Calc!$AN$3:$AN$122,0),"")
A16: =IF(AND(ISNUMBER($T16),$T16<>""),INDEX(Calc!$S$3:$S$122,$T16),"") | B16: =IF(AND(ISNUMBER($T16),$T16<>""),IF(INDEX(Calc!$T$3:$T$122,$T16)="","—",INDEX(Calc!$T$3:$T$122,$T16)),"") | C16: =IF(AND(ISNUMBER($T16),$T16<>""),IF(INDEX(Calc!$U$3:$U$122,$T16)="","—",INDEX(Calc!$U$3:$U$122,$T16)),"") | D16: =IF(AND(ISNUMBER($T16),$T16<>""),IF(INDEX(Calc!$V$3:$V$122,$T16)="","—",INDEX(Calc!$V$3:$V$122,$T16)),"") | E16: =IF(AND(ISNUMBER($T16),$T16<>""),IF(INDEX(Calc!$W$3:$W$122,$T16)="","—",INDEX(Calc!$W$3:$W$122,$T16)),"") | F16: =IF(AND(ISNUMBER($T16),$T16<>""),IF(INDEX(Calc!$X$3:$X$122,$T16)="","—",INDEX(Calc!$X$3:$X$122,$T16)),"") | G16: =IF(AND(ISNUMBER($T16),$T16<>""),IF(INDEX(Calc!$Y$3:$Y$122,$T16)="","—",INDEX(Calc!$Y$3:$Y$122,$T16)),"") | H16: =IF(AND(ISNUMBER($T16),$T16<>""),IF(INDEX(Calc!$Z$3:$Z$122,$T16)="","—",INDEX(Calc!$Z$3:$Z$122,$T16)),"") | I16: =IF(AND(ISNUMBER($T16),$T16<>""),IF(INDEX(Calc!$AA$3:$AA$122,$T16)="","—",INDEX(Calc!$AA$3:$AA$122,$T16)),"") | J16: =IF(AND(ISNUMBER($T16),$T16<>""),IF(INDEX(Calc!$AB$3:$AB$122,$T16)="","—",INDEX(Calc!$AB$3:$AB$122,$T16)),"") | K16: =IF(AND(ISNUMBER($T16),$T16<>""),IF(INDEX(Calc!$AC$3:$AC$122,$T16)="","—",INDEX(Calc!$AC$3:$AC$122,$T16)),"") | L16: =IF(AND(ISNUMBER($T16),$T16<>""),IF(INDEX(Calc!$AD$3:$AD$122,$T16)="","—",INDEX(Calc!$AD$3:$AD$122,$T16)),"") | M16: =IF(AND(ISNUMBER($T16),$T16<>""),IF(INDEX(Calc!$AE$3:$AE$122,$T16)="","—",INDEX(Calc!$AE$3:$AE$122,$T16)),"") | N16: =IF(AND(ISNUMBER($T16),$T16<>""),IF(INDEX(Calc!$AF$3:$AF$122,$T16)="","—",INDEX(Calc!$AF$3:$AF$122,$T16)),"") | O16: =IF(AND(ISNUMBER($T16),$T16<>""),IF(INDEX(Calc!$AG$3:$AG$122,$T16)="","—",INDEX(Calc!$AG$3:$AG$122,$T16)),"") | P16: =IF(AND(ISNUMBER($T16),$T16<>""),IF(INDEX(Calc!$AJ$3:$AJ$122,$T16)="","—",INDEX(Calc!$AJ$3:$AJ$122,$T16)),"") | Q16: =IF(AND(ISNUMBER($T16),$T16<>""),IF(INDEX(Calc!$AK$3:$AK$122,$T16)="","—",INDEX(Calc!$AK$3:$AK$122,$T16)),"") | R16: =IF(AND(ISNUMBER($T16),$T16<>""),IF(INDEX(Calc!$AL$3:$AL$122,$T16)="","—",INDEX(Calc!$AL$3:$AL$122,$T16)),"") | T16: =IFERROR(MATCH(12,Calc!$AN$3:$AN$122,0),"")
